Workbook

Sheet Invulblad
W1: = Uitbesteed
W2: = Afgeleverd
W3: = Gereed
S4: Als order is afgeleverd, BEIDE op Afgevelerd zetten | W4: = Bij coater/verzinkerij
B5: Ordernummer: | C5: Omschrijving: | D5: Klant: | E5: Week: | F5: Totale uren: | G5: Medewerker 1: | H5: % uren 1: | I5: Uren 1: | J5: Medewerker 2: | K5: % uren 2: | L5: Uren 2: | M5: Medewerker 3: | N5: % uren 3: | O5: Uren 3: | P5: Controle % | Q5: Datum coater/verzinkerij: | R5: Datum gereed: | S5: Status: | T5: Hulpmaterialen: | W5: = Niet invullen!
I6: =IF(Tabel1[[#This Row],[% uren 1:]]="","",Tabel1[[#This Row],[% uren 1:]]*Tabel1[[#This Row],[Totale uren:]]) | L6: =IF(Tabel1[[#This Row],[% uren 2:]]="","",Tabel1[[#This Row],[% uren 2:]]*Tabel1[[#This Row],[Totale uren:]]) | O6: =IF(Tabel1[[#This Row],[% uren 3:]]="","",Tabel1[[#This Row],[% uren 3:]]*Tabel1[[#This Row],[Totale uren:]]) | P6: =IF(Tabel1[[#This Row],[Ordernummer:]]="","",SUM(Tabel1[[#This Row],[% uren 1:]],Tabel1[[#This Row],[% uren 2:]],Tabel1[[#This Row],[% uren 3:]]))
I7: =IF(Tabel1[[#This Row],[% uren 1:]]="","",Tabel1[[#This Row],[% uren 1:]]*Tabel1[[#This Row],[Totale uren:]]) | L7: =IF(Tabel1[[#This Row],[% uren 2:]]="","",Tabel1[[#This Row],[% uren 2:]]*Tabel1[[#This Row],[Totale uren:]]) | O7: =IF(Tabel1[[#This Row],[% uren 3:]]="","",Tabel1[[#This Row],[% uren 3:]]*Tabel1[[#This Row],[Totale uren:]]) | P7: =IF(Tabel1[[#This Row],[Ordernummer:]]="","",SUM(Tabel1[[#This Row],[% uren 1:]],Tabel1[[#This Row],[% uren 2:]],Tabel1[[#This Row],[% uren 3:]]))
I8: =IF(Tabel1[[#This Row],[% uren 1:]]="","",Tabel1[[#This Row],[% uren 1:]]*Tabel1[[#This Row],[Totale uren:]]) | L8: =IF(Tabel1[[#This Row],[% uren 2:]]="","",Tabel1[[#This Row],[% uren 2:]]*Tabel1[[#This Row],[Totale uren:]]) | O8: =IF(Tabel1[[#This Row],[% uren 3:]]="","",Tabel1[[#This Row],[% uren 3:]]*Tabel1[[#This Row],[Totale uren:]]) | P8: =IF(Tabel1[[#This Row],[Ordernummer:]]="","",SUM(Tabel1[[#This Row],[% uren 1:]],Tabel1[[#This Row],[% uren 2:]],Tabel1[[#This Row],[% uren 3:]]))
I9: =IF(Tabel1[[#This Row],[% uren 1:]]="","",Tabel1[[#This Row],[% uren 1:]]*Tabel1[[#This Row],[Totale uren:]]) | L9: =IF(Tabel1[[#This Row],[% uren 2:]]="","",Tabel1[[#This Row],[% uren 2:]]*Tabel1[[#This Row],[Totale uren:]]) | O9: =IF(Tabel1[[#This Row],[% uren 3:]]="","",Tabel1[[#This Row],[% uren 3:]]*Tabel1[[#This Row],[Totale uren:]]) | P9: =IF(Tabel1[[#This Row],[Ordernummer:]]="","",SUM(Tabel1[[#This Row],[% uren 1:]],Tabel1[[#This Row],[% uren 2:]],Tabel1[[#This Row],[% uren 3:]]))
I10: =IF(Tabel1[[#This Row],[% uren 1:]]="","",Tabel1[[#This Row],[% uren 1:]]*Tabel1[[#This Row],[Totale uren:]]) | L10: =IF(Tabel1[[#This Row],[% uren 2:]]="","",Tabel1[[#This Row],[% uren 2:]]*Tabel1[[#This Row],[Totale uren:]]) | O10: =IF(Tabel1[[#This Row],[% uren 3:]]="","",Tabel1[[#This Row],[% uren 3:]]*Tabel1[[#This Row],[Totale uren:]]) | P10: =IF(Tabel1[[#This Row],[Ordernummer:]]="","",SUM(Tabel1[[#This Row],[% uren 1:]],Tabel1[[#This Row],[% uren 2:]],Tabel1[[#This Row],[% uren 3:]]))
I11: =IF(Tabel1[[#This Row],[% uren 1:]]="","",Tabel1[[#This Row],[% uren 1:]]*Tabel1[[#This Row],[Totale uren:]]) | L11: =IF(Tabel1[[#This Row],[% uren 2:]]="","",Tabel1[[#This Row],[% uren 2:]]*Tabel1[[#This Row],[Totale uren:]]) | O11: =IF(Tabel1[[#This Row],[% uren 3:]]="","",Tabel1[[#This Row],[% uren 3:]]*Tabel1[[#This Row],[Totale uren:]]) | P11: =IF(Tabel1[[#This Row],[Ordernummer:]]="","",SUM(Tabel1[[#This Row],[% uren 1:]],Tabel1[[#This Row],[% uren 2:]],Tabel1[[#This Row],[% uren 3:]]))
I12: =IF(Tabel1[[#This Row],[% uren 1:]]="","",Tabel1[[#This Row],[% uren 1:]]*Tabel1[[#This Row],[Totale uren:]]) | L12: =IF(Tabel1[[#This Row],[% uren 2:]]="","",Tabel1[[#This Row],[% uren 2:]]*Tabel1[[#This Row],[Totale uren:]]) | O12: =IF(Tabel1[[#This Row],[% uren 3:]]="","",Tabel1[[#This Row],[% uren 3:]]*Tabel1[[#This Row],[Totale uren:]]) | P12: =IF(Tabel1[[#This Row],[Ordernummer:]]="","",SUM(Tabel1[[#This Row],[% uren 1:]],Tabel1[[#This Row],[% uren 2:]],Tabel1[[#This Row],[% uren 3:]]))
I13: =IF(Tabel1[[#This Row],[% uren 1:]]="","",Tabel1[[#This Row],[% uren 1:]]*Tabel1[[#This Row],[Totale uren:]]) | L13: =IF(Tabel1[[#This Row],[% uren 2:]]="","",Tabel1[[#This Row],[% uren 2:]]*Tabel1[[#This Row],[Totale uren:]]) | O13: =IF(Tabel1[[#This Row],[% uren 3:]]="","",Tabel1[[#This Row],[% uren 3:]]*Tabel1[[#This Row],[Totale uren:]]) | P13: =IF(Tabel1[[#This Row],[Ordernummer:]]="","",SUM(Tabel1[[#This Row],[% uren 1:]],Tabel1[[#This Row],[% uren 2:]],Tabel1[[#This Row],[% uren 3:]]))
I14: =IF(Tabel1[[#This Row],[% uren 1:]]="","",Tabel1[[#This Row],[% uren 1:]]*Tabel1[[#This Row],[Totale uren:]]) | L14: =IF(Tabel1[[#This Row],[% uren 2:]]="","",Tabel1[[#This Row],[% uren 2:]]*Tabel1[[#This Row],[Totale uren:]]) | O14: =IF(Tabel1[[#This Row],[% uren 3:]]="","",Tabel1[[#This Row],[% uren 3:]]*Tabel1[[#This Row],[Totale uren:]]) | P14: =IF(Tabel1[[#This Row],[Ordernummer:]]="","",SUM(Tabel1[[#This Row],[% uren 1:]],Tabel1[[#This Row],[% uren 2:]],Tabel1[[#This Row],[% uren 3:]]))
I15: =IF(Tabel1[[#This Row],[% uren 1:]]="","",Tabel1[[#This Row],[% uren 1:]]*Tabel1[[#This Row],[Totale uren:]]) | L15: =IF(Tabel1[[#This Row],[% uren 2:]]="","",Tabel1[[#This Row],[% uren 2:]]*Tabel1[[#This Row],[Totale uren:]]) | O15: =IF(Tabel1[[#This Row],[% uren 3:]]="","",Tabel1[[#This Row],[% uren 3:]]*Tabel1[[#This Row],[Totale uren:]]) | P15: =IF(Tabel1[[#This Row],[Ordernummer:]]="","",SUM(Tabel1[[#This Row],[% uren 1:]],Tabel1[[#This Row],[% uren 2:]],Tabel1[[#This Row],[% uren 3:]]))
I16: =IF(Tabel1[[#This Row],[% uren 1:]]="","",Tabel1[[#This Row],[% uren 1:]]*Tabel1[[#This Row],[Totale uren:]]) | L16: =IF(Tabel1[[#This Row],[% uren 2:]]="","",Tabel1[[#This Row],[% uren 2:]]*Tabel1[[#This Row],[Totale uren:]]) | O16: =IF(Tabel1[[#This Row],[% uren 3:]]="","",Tabel1[[#This Row],[% uren 3:]]*Tabel1[[#This Row],[Totale uren:]]) | P16: =IF(Tabel1[[#This Row],[Ordernummer:]]="","",SUM(Tabel1[[#This Row],[% uren 1:]],Tabel1[[#This Row],[% uren 2:]],Tabel1[[#This Row],[% uren 3:]]))
I17: =IF(Tabel1[[#This Row],[% uren 1:]]="","",Tabel1[[#This Row],[% uren 1:]]*Tabel1[[#This Row],[Totale uren:]]) | L17: =IF(Tabel1[[#This Row],[% uren 2:]]="","",Tabel1[[#This Row],[% uren 2:]]*Tabel1[[#This Row],[Totale uren:]]) | O17: =IF(Tabel1[[#This Row],[% uren 3:]]="","",Tabel1[[#This Row],[% uren 3:]]*Tabel1[[#This Row],[Totale uren:]]) | P17: =IF(Tabel1[[#This Row],[Ordernummer:]]="","",SUM(Tabel1[[#This Row],[% uren 1:]],Tabel1[[#This Row],[% uren 2:]],Tabel1[[#This Row],[% uren 3:]]))
... I1003: =IF(Tabel1[[#This Row],[% uren 1:]]="","",Tabel1[[#This Row],[% uren 1:]]*Tabel1[[#This Row],[Totale uren:]]) | L1003: =IF(Tabel1[[#This Row],[% uren 2:]]="","",Tabel1[[#This Row],[% uren 2:]]*Tabel1[[#This Row],[Totale uren:]]) | O1003: =IF(Tabel1[[#This Row],[% uren 3:]]="","",Tabel1[[#This Row],[% uren 3:]]*Tabel1[[#This Row],[Totale uren:]]) | P1003: =IF(Tabel1[[#This Row],[Ordernummer:]]="","",SUM(Tabel1[[#This Row],[% uren 1:]],Tabel1[[#This Row],[% uren 2:]],Tabel1[[#This Row],[% uren 3:]]))

Sheet Dashboard
B2: Orderstatus | AQ2: Hulpmaterialen
C3: 1 - Werkvoorbereiding | P3: 4 - Materiaal binnen | AC3: 7 - Klaar voor coater/verzinkerij | AR3: Hulpmaterialen - Nog bestellen
C4: Order | E4: Omschrijving | J4: Klant | N4: Week | P4: Order | R4: Omschrijving | W4: Klant | AA4: Week | AC4: Order | AE4: Omschrijving | AJ4: Klant | AN4: Week | AR4: Order | AT4: Omschrijving | AY4: Klant | BC4: Week
C5: =IFERROR(IF('Ber. st. 1'!B4=0,"",'Ber. st. 1'!B4),"") | E5: =IF('Ber. st. 1'!C4=0,"",'Ber. st. 1'!C4) | J5: =IF('Ber. st. 1'!D4=0,"",'Ber. st. 1'!D4) | N5: =IF('Ber. st. 1'!E4=0,"",'Ber. st. 1'!E4) | P5: =IFERROR(IF('Ber. st. 4'!B4=0,"",'Ber. st. 4'!B4),"") | R5: =IF('Ber. st. 4'!C4=0,"",'Ber. st. 4'!C4) | W5: =IF('Ber. st. 4'!D4=0,"",'Ber. st. 4'!D4) | AA5: =IF('Ber. st. 4'!E4=0,"",'Ber. st. 4'!E4) | AC5: =IFERROR(IF('Ber. st. 7'!B4=0,"",'Ber. st. 7'!B4),"") | AE5: =IF('Ber. st. 7'!C4=0,"",'Ber. st. 7'!C4) | AJ5: =IF('Ber. st. 7'!D4=0,"",'Ber. st. 7'!D4) | AN5: =IF('Ber. st. 7'!E4=0,"",'Ber. st. 7'!E4) | AR5: =IFERROR(IF('Ber. Hulpmateriaal'!B4=0,"",'Ber. Hulpmateriaal'!B4),"") | AT5: =IF('Ber. Hulpmateriaal'!C4=0,"",'Ber. Hulpmateriaal'!C4) | AY5: =IF('Ber. Hulpmateriaal'!D4=0,"",'Ber. Hulpmateriaal'!D4) | BC5: =IF('Ber. Hulpmateriaal'!E4=0,"",'Ber. Hulpmateriaal'!E4)
C6: =IF('Ber. st. 1'!B5=0,"",'Ber. st. 1'!B5) | E6: =IF('Ber. st. 1'!C5=0,"",'Ber. st. 1'!C5) | J6: =IF('Ber. st. 1'!D5=0,"",'Ber. st. 1'!D5) | N6: =IF('Ber. st. 1'!E5=0,"",'Ber. st. 1'!E5) | P6: =IF('Ber. st. 4'!B5=0,"",'Ber. st. 4'!B5) | R6: =IF('Ber. st. 4'!C5=0,"",'Ber. st. 4'!C5) | W6: =IF('Ber. st. 4'!D5=0,"",'Ber. st. 4'!D5) | AA6: =IF('Ber. st. 4'!E5=0,"",'Ber. st. 4'!E5) | AC6: =IF('Ber. st. 7'!B5=0,"",'Ber. st. 7'!B5) | AE6: =IF('Ber. st. 7'!C5=0,"",'Ber. st. 7'!C5) | AJ6: =IF('Ber. st. 7'!D5=0,"",'Ber. st. 7'!D5) | AN6: =IF('Ber. st. 7'!E5=0,"",'Ber. st. 7'!E5) | AR6: =IF('Ber. Hulpmateriaal'!B5=0,"",'Ber. Hulpmateriaal'!B5) | AT6: =IF('Ber. Hulpmateriaal'!C5=0,"",'Ber. Hulpmateriaal'!C5) | AY6: =IF('Ber. Hulpmateriaal'!D5=0,"",'Ber. Hulpmateriaal'!D5) | BC6: =IF('Ber. Hulpmateriaal'!E5=0,"",'Ber. Hulpmateriaal'!E5)
C7: =IF('Ber. st. 1'!B6=0,"",'Ber. st. 1'!B6) | E7: =IF('Ber. st. 1'!C6=0,"",'Ber. st. 1'!C6) | J7: =IF('Ber. st. 1'!D6=0,"",'Ber. st. 1'!D6) | N7: =IF('Ber. st. 1'!E6=0,"",'Ber. st. 1'!E6) | P7: =IF('Ber. st. 4'!B6=0,"",'Ber. st. 4'!B6) | R7: =IF('Ber. st. 4'!C6=0,"",'Ber. st. 4'!C6) | W7: =IF('Ber. st. 4'!D6=0,"",'Ber. st. 4'!D6) | AA7: =IF('Ber. st. 4'!E6=0,"",'Ber. st. 4'!E6) | AC7: =IF('Ber. st. 7'!B6=0,"",'Ber. st. 7'!B6) | AE7: =IF('Ber. st. 7'!C6=0,"",'Ber. st. 7'!C6) | AJ7: =IF('Ber. st. 7'!D6=0,"",'Ber. st. 7'!D6) | AN7: =IF('Ber. st. 7'!E6=0,"",'Ber. st. 7'!E6) | AR7: =IF('Ber. Hulpmateriaal'!B6=0,"",'Ber. Hulpmateriaal'!B6) | AT7: =IF('Ber. Hulpmateriaal'!C6=0,"",'Ber. Hulpmateriaal'!C6) | AY7: =IF('Ber. Hulpmateriaal'!D6=0,"",'Ber. Hulpmateriaal'!D6) | BC7: =IF('Ber. Hulpmateriaal'!E6=0,"",'Ber. Hulpmateriaal'!E6)
C8: =IF('Ber. st. 1'!B7=0,"",'Ber. st. 1'!B7) | E8: =IF('Ber. st. 1'!C7=0,"",'Ber. st. 1'!C7) | J8: =IF('Ber. st. 1'!D7=0,"",'Ber. st. 1'!D7) | N8: =IF('Ber. st. 1'!E7=0,"",'Ber. st. 1'!E7) | P8: =IF('Ber. st. 4'!B7=0,"",'Ber. st. 4'!B7) | R8: =IF('Ber. st. 4'!C7=0,"",'Ber. st. 4'!C7) | W8: =IF('Ber. st. 4'!D7=0,"",'Ber. st. 4'!D7) | AA8: =IF('Ber. st. 4'!E7=0,"",'Ber. st. 4'!E7) | AC8: =IF('Ber. st. 7'!B7=0,"",'Ber. st. 7'!B7) | AE8: =IF('Ber. st. 7'!C7=0,"",'Ber. st. 7'!C7) | AJ8: =IF('Ber. st. 7'!D7=0,"",'Ber. st. 7'!D7) | AN8: =IF('Ber. st. 7'!E7=0,"",'Ber. st. 7'!E7) | AR8: =IF('Ber. Hulpmateriaal'!B7=0,"",'Ber. Hulpmateriaal'!B7) | AT8: =IF('Ber. Hulpmateriaal'!C7=0,"",'Ber. Hulpmateriaal'!C7) | AY8: =IF('Ber. Hulpmateriaal'!D7=0,"",'Ber. Hulpmateriaal'!D7) | BC8: =IF('Ber. Hulpmateriaal'!E7=0,"",'Ber. Hulpmateriaal'!E7)
C9: =IF('Ber. st. 1'!B8=0,"",'Ber. st. 1'!B8) | E9: =IF('Ber. st. 1'!C8=0,"",'Ber. st. 1'!C8) | J9: =IF('Ber. st. 1'!D8=0,"",'Ber. st. 1'!D8) | N9: =IF('Ber. st. 1'!E8=0,"",'Ber. st. 1'!E8) | P9: =IF('Ber. st. 4'!B8=0,"",'Ber. st. 4'!B8) | R9: =IF('Ber. st. 4'!C8=0,"",'Ber. st. 4'!C8) | W9: =IF('Ber. st. 4'!D8=0,"",'Ber. st. 4'!D8) | AA9: =IF('Ber. st. 4'!E8=0,"",'Ber. st. 4'!E8) | AC9: =IF('Ber. st. 7'!B8=0,"",'Ber. st. 7'!B8) | AE9: =IF('Ber. st. 7'!C8=0,"",'Ber. st. 7'!C8) | AJ9: =IF('Ber. st. 7'!D8=0,"",'Ber. st. 7'!D8) | AN9: =IF('Ber. st. 7'!E8=0,"",'Ber. st. 7'!E8) | AR9: =IF('Ber. Hulpmateriaal'!B8=0,"",'Ber. Hulpmateriaal'!B8) | AT9: =IF('Ber. Hulpmateriaal'!C8=0,"",'Ber. Hulpmateriaal'!C8) | AY9: =IF('Ber. Hulpmateriaal'!D8=0,"",'Ber. Hulpmateriaal'!D8) | BC9: =IF('Ber. Hulpmateriaal'!E8=0,"",'Ber. Hulpmateriaal'!E8)
C10: =IF('Ber. st. 1'!B9=0,"",'Ber. st. 1'!B9) | E10: =IF('Ber. st. 1'!C9=0,"",'Ber. st. 1'!C9) | J10: =IF('Ber. st. 1'!D9=0,"",'Ber. st. 1'!D9) | N10: =IF('Ber. st. 1'!E9=0,"",'Ber. st. 1'!E9) | P10: =IF('Ber. st. 4'!B9=0,"",'Ber. st. 4'!B9) | R10: =IF('Ber. st. 4'!C9=0,"",'Ber. st. 4'!C9) | W10: =IF('Ber. st. 4'!D9=0,"",'Ber. st. 4'!D9) | AA10: =IF('Ber. st. 4'!E9=0,"",'Ber. st. 4'!E9) | AC10: =IF('Ber. st. 7'!B9=0,"",'Ber. st. 7'!B9) | AE10: =IF('Ber. st. 7'!C9=0,"",'Ber. st. 7'!C9) | AJ10: =IF('Ber. st. 7'!D9=0,"",'Ber. st. 7'!D9) | AN10: =IF('Ber. st. 7'!E9=0,"",'Ber. st. 7'!E9)
C11: =IF('Ber. st. 1'!B10=0,"",'Ber. st. 1'!B10) | E11: =IF('Ber. st. 1'!C10=0,"",'Ber. st. 1'!C10) | J11: =IF('Ber. st. 1'!D10=0,"",'Ber. st. 1'!D10) | N11: =IF('Ber. st. 1'!E10=0,"",'Ber. st. 1'!E10) | P11: =IF('Ber. st. 4'!B10=0,"",'Ber. st. 4'!B10) | R11: =IF('Ber. st. 4'!C10=0,"",'Ber. st. 4'!C10) | W11: =IF('Ber. st. 4'!D10=0,"",'Ber. st. 4'!D10) | AA11: =IF('Ber. st. 4'!E10=0,"",'Ber. st. 4'!E10) | AC11: =IF('Ber. st. 7'!B10=0,"",'Ber. st. 7'!B10) | AE11: =IF('Ber. st. 7'!C10=0,"",'Ber. st. 7'!C10) | AJ11: =IF('Ber. st. 7'!D10=0,"",'Ber. st. 7'!D10) | AN11: =IF('Ber. st. 7'!E10=0,"",'Ber. st. 7'!E10) | AR11: Hulpmaterialen - Besteld
AR12: Order | AT12: Omschrijving | AY12: Klant | BC12: Week
C13: 2 - Materiaal deels besteld | P13: 5 - Voorbereiden (Nobelweg 2B) | AC13: 8 - Bij coater/verzinkerij | AR13: =IFERROR(IF('Ber. Hulpmateriaal'!B17=0,"",'Ber. Hulpmateriaal'!B17),"") | AT13: =IF('Ber. Hulpmateriaal'!C17=0,"",'Ber. Hulpmateriaal'!C17) | AY13: =IF('Ber. Hulpmateriaal'!D17=0,"",'Ber. Hulpmateriaal'!D17) | BC13: =IF('Ber. Hulpmateriaal'!E17=0,"",'Ber. Hulpmateriaal'!E17)
C14: Order | E14: Omschrijving | J14: Klant | N14: Week | P14: Order | R14: Omschrijving | W14: Klant | AA14: Week | AC14: Order | AE14: Omschrijving | AJ14: Klant | AN14: Week | AR14: =IF('Ber. Hulpmateriaal'!B18=0,"",'Ber. Hulpmateriaal'!B18) | AT14: =IF('Ber. Hulpmateriaal'!C18=0,"",'Ber. Hulpmateriaal'!C18) | AY14: =IF('Ber. Hulpmateriaal'!D18=0,"",'Ber. Hulpmateriaal'!D18) | BC14: =IF('Ber. Hulpmateriaal'!E18=0,"",'Ber. Hulpmateriaal'!E18)
C15: =IFERROR(IF('Ber. st. 2'!B4=0,"",'Ber. st. 2'!B4),"") | E15: =IF('Ber. st. 2'!C4=0,"",'Ber. st. 2'!C4) | J15: =IF('Ber. st. 2'!D4=0,"",'Ber. st. 2'!D4) | N15: =IF('Ber. st. 2'!E4=0,"",'Ber. st. 2'!E4) | P15: =IFERROR(IF('Ber. st. 5'!B4=0,"",'Ber. st. 5'!B4),"") | R15: =IF('Ber. st. 5'!C4=0,"",'Ber. st. 5'!C4) | W15: =IF('Ber. st. 5'!D4=0,"",'Ber. st. 5'!D4) | AA15: =IF('Ber. st. 5'!E4=0,"",'Ber. st. 5'!E4) | AC15: =IFERROR(IF('Ber. st. 8'!B4=0,"",'Ber. st. 8'!B4),"") | AE15: =IF('Ber. st. 8'!C4=0,"",'Ber. st. 8'!C4) | AJ15: =IF('Ber. st. 8'!D4=0,"",'Ber. st. 8'!D4) | AN15: =IF('Ber. st. 8'!E4=0,"",'Ber. st. 8'!E4) | AR15: =IF('Ber. Hulpmateriaal'!B19=0,"",'Ber. Hulpmateriaal'!B19) | AT15: =IF('Ber. Hulpmateriaal'!C19=0,"",'Ber. Hulpmateriaal'!C19) | AY15: =IF('Ber. Hulpmateriaal'!D19=0,"",'Ber. Hulpmateriaal'!D19) | BC15: =IF('Ber. Hulpmateriaal'!E19=0,"",'Ber. Hulpmateriaal'!E19)
C16: =IF('Ber. st. 2'!B5=0,"",'Ber. st. 2'!B5) | E16: =IF('Ber. st. 2'!C5=0,"",'Ber. st. 2'!C5) | J16: =IF('Ber. st. 2'!D5=0,"",'Ber. st. 2'!D5) | N16: =IF('Ber. st. 2'!E5=0,"",'Ber. st. 2'!E5) | P16: =IF('Ber. st. 5'!B5=0,"",'Ber. st. 5'!B5) | R16: =IF('Ber. st. 5'!C5=0,"",'Ber. st. 5'!C5) | W16: =IF('Ber. st. 5'!D5=0,"",'Ber. st. 5'!D5) | AA16: =IF('Ber. st. 5'!E5=0,"",'Ber. st. 5'!E5) | AC16: =IF('Ber. st. 8'!B5=0,"",'Ber. st. 8'!B5) | AE16: =IF('Ber. st. 8'!C5=0,"",'Ber. st. 8'!C5) | AJ16: =IF('Ber. st. 8'!D5=0,"",'Ber. st. 8'!D5) | AN16: =IF('Ber. st. 8'!E5=0,"",'Ber. st. 8'!E5) | AR16: =IF('Ber. Hulpmateriaal'!B20=0,"",'Ber. Hulpmateriaal'!B20) | AT16: =IF('Ber. Hulpmateriaal'!C20=0,"",'Ber. Hulpmateriaal'!C20) | AY16: =IF('Ber. Hulpmateriaal'!D20=0,"",'Ber. Hulpmateriaal'!D20) | BC16: =IF('Ber. Hulpmateriaal'!E20=0,"",'Ber. Hulpmateriaal'!E20)
C17: =IF('Ber. st. 2'!B6=0,"",'Ber. st. 2'!B6) | E17: =IF('Ber. st. 2'!C6=0,"",'Ber. st. 2'!C6) | J17: =IF('Ber. st. 2'!D6=0,"",'Ber. st. 2'!D6) | N17: =IF('Ber. st. 2'!E6=0,"",'Ber. st. 2'!E6) | P17: =IF('Ber. st. 5'!B6=0,"",'Ber. st. 5'!B6) | R17: =IF('Ber. st. 5'!C6=0,"",'Ber. st. 5'!C6) | W17: =IF('Ber. st. 5'!D6=0,"",'Ber. st. 5'!D6) | AA17: =IF('Ber. st. 5'!E6=0,"",'Ber. st. 5'!E6) | AC17: =IF('Ber. st. 8'!B6=0,"",'Ber. st. 8'!B6) | AE17: =IF('Ber. st. 8'!C6=0,"",'Ber. st. 8'!C6) | AJ17: =IF('Ber. st. 8'!D6=0,"",'Ber. st. 8'!D6) | AN17: =IF('Ber. st. 8'!E6=0,"",'Ber. st. 8'!E6) | AR17: =IF('Ber. Hulpmateriaal'!B21=0,"",'Ber. Hulpmateriaal'!B21) | AT17: =IF('Ber. Hulpmateriaal'!C21=0,"",'Ber. Hulpmateriaal'!C21) | AY17: =IF('Ber. Hulpmateriaal'!D21=0,"",'Ber. Hulpmateriaal'!D21) | BC17: =IF('Ber. Hulpmateriaal'!E21=0,"",'Ber. Hulpmateriaal'!E21)
C18: =IF('Ber. st. 2'!B7=0,"",'Ber. st. 2'!B7) | E18: =IF('Ber. st. 2'!C7=0,"",'Ber. st. 2'!C7) | J18: =IF('Ber. st. 2'!D7=0,"",'Ber. st. 2'!D7) | N18: =IF('Ber. st. 2'!E7=0,"",'Ber. st. 2'!E7) | P18: =IF('Ber. st. 5'!B7=0,"",'Ber. st. 5'!B7) | R18: =IF('Ber. st. 5'!C7=0,"",'Ber. st. 5'!C7) | W18: =IF('Ber. st. 5'!D7=0,"",'Ber. st. 5'!D7) | AA18: =IF('Ber. st. 5'!E7=0,"",'Ber. st. 5'!E7) | AC18: =IF('Ber. st. 8'!B7=0,"",'Ber. st. 8'!B7) | AE18: =IF('Ber. st. 8'!C7=0,"",'Ber. st. 8'!C7) | AJ18: =IF('Ber. st. 8'!D7=0,"",'Ber. st. 8'!D7) | AN18: =IF('Ber. st. 8'!E7=0,"",'Ber. st. 8'!E7)
C19: =IF('Ber. st. 2'!B8=0,"",'Ber. st. 2'!B8) | E19: =IF('Ber. st. 2'!C8=0,"",'Ber. st. 2'!C8) | J19: =IF('Ber. st. 2'!D8=0,"",'Ber. st. 2'!D8) | N19: =IF('Ber. st. 2'!E8=0,"",'Ber. st. 2'!E8) | P19: =IF('Ber. st. 5'!B8=0,"",'Ber. st. 5'!B8) | R19: =IF('Ber. st. 5'!C8=0,"",'Ber. st. 5'!C8) | W19: =IF('Ber. st. 5'!D8=0,"",'Ber. st. 5'!D8) | AA19: =IF('Ber. st. 5'!E8=0,"",'Ber. st. 5'!E8) | AC19: =IF('Ber. st. 8'!B8=0,"",'Ber. st. 8'!B8) | AE19: =IF('Ber. st. 8'!C8=0,"",'Ber. st. 8'!C8) | AJ19: =IF('Ber. st. 8'!D8=0,"",'Ber. st. 8'!D8) | AN19: =IF('Ber. st. 8'!E8=0,"",'Ber. st. 8'!E8) | AR19: Hulpmaterialen - Compleet
AR20: Order | AT20: Omschrijving | AY20: Klant | BC20: Week
C21: 3 - Materiaal besteld | P21: 6 - In productie (Nobelweg 3) | AC21: 9 - Gereed, kan worden opgehaald | AR21: =IFERROR(IF('Ber. Hulpmateriaal'!B30=0,"",'Ber. Hulpmateriaal'!B30),"") | AT21: =IF('Ber. Hulpmateriaal'!C30=0,"",'Ber. Hulpmateriaal'!C30) | AY21: =IF('Ber. Hulpmateriaal'!D30=0,"",'Ber. Hulpmateriaal'!D30) | BC21: =IF('Ber. Hulpmateriaal'!E30=0,"",'Ber. Hulpmateriaal'!E30)
C22: Order | E22: Omschrijving | J22: Klant | N22: Week | P22: Order | R22: Omschrijving | W22: Klant | AA22: Week | AC22: Order | AE22: Omschrijving | AJ22: Klant | AN22: Week | AR22: =IF('Ber. Hulpmateriaal'!B31=0,"",'Ber. Hulpmateriaal'!B31) | AT22: =IF('Ber. Hulpmateriaal'!C31=0,"",'Ber. Hulpmateriaal'!C31) | AY22: =IF('Ber. Hulpmateriaal'!D31=0,"",'Ber. Hulpmateriaal'!D31) | BC22: =IF('Ber. Hulpmateriaal'!E31=0,"",'Ber. Hulpmateriaal'!E31)
C23: =IFERROR(IF('Ber. st. 3'!B4=0,"",'Ber. st. 3'!B4),"") | E23: =IF('Ber. st. 3'!C4=0,"",'Ber. st. 3'!C4) | J23: =IF('Ber. st. 3'!D4=0,"",'Ber. st. 3'!D4) | N23: =IF('Ber. st. 3'!E4=0,"",'Ber. st. 3'!E4) | P23: =IFERROR(IF('Ber. st. 6'!B4=0,"",'Ber. st. 6'!B4),"") | R23: =IF('Ber. st. 6'!C4=0,"",'Ber. st. 6'!C4) | W23: =IF('Ber. st. 6'!D4=0,"",'Ber. st. 6'!D4) | AA23: =IF('Ber. st. 6'!E4=0,"",'Ber. st. 6'!E4) | AC23: =IFERROR(IF('Ber. st. 9'!B4=0,"",'Ber. st. 9'!B4),"") | AE23: =IF('Ber. st. 9'!C4=0,"",'Ber. st. 9'!C4) | AJ23: =IF('Ber. st. 9'!D4=0,"",'Ber. st. 9'!D4) | AN23: =IF('Ber. st. 9'!E4=0,"",'Ber. st. 9'!E4) | AR23: =IF('Ber. Hulpmateriaal'!B32=0,"",'Ber. Hulpmateriaal'!B32) | AT23: =IF('Ber. Hulpmateriaal'!C32=0,"",'Ber. Hulpmateriaal'!C32) | AY23: =IF('Ber. Hulpmateriaal'!D32=0,"",'Ber. Hulpmateriaal'!D32) | BC23: =IF('Ber. Hulpmateriaal'!E32=0,"",'Ber. Hulpmateriaal'!E32)
C24: =IF('Ber. st. 3'!B5=0,"",'Ber. st. 3'!B5) | E24: =IF('Ber. st. 3'!C5=0,"",'Ber. st. 3'!C5) | J24: =IF('Ber. st. 3'!D5=0,"",'Ber. st. 3'!D5) | N24: =IF('Ber. st. 3'!E5=0,"",'Ber. st. 3'!E5) | P24: =IF('Ber. st. 6'!B5=0,"",'Ber. st. 6'!B5) | R24: =IF('Ber. st. 6'!C5=0,"",'Ber. st. 6'!C5) | W24: =IF('Ber. st. 6'!D5=0,"",'Ber. st. 6'!D5) | AA24: =IF('Ber. st. 6'!E5=0,"",'Ber. st. 6'!E5) | AC24: =IF('Ber. st. 9'!B5=0,"",'Ber. st. 9'!B5) | AE24: =IF('Ber. st. 9'!C5=0,"",'Ber. st. 9'!C5) | AJ24: =IF('Ber. st. 9'!D5=0,"",'Ber. st. 9'!D5) | AN24: =IF('Ber. st. 9'!E5=0,"",'Ber. st. 9'!E5) | AR24: =IF('Ber. Hulpmateriaal'!B33=0,"",'Ber. Hulpmateriaal'!B33) | AT24: =IF('Ber. Hulpmateriaal'!C33=0,"",'Ber. Hulpmateriaal'!C33) | AY24: =IF('Ber. Hulpmateriaal'!D33=0,"",'Ber. Hulpmateriaal'!D33) | BC24: =IF('Ber. Hulpmateriaal'!E33=0,"",'Ber. Hulpmateriaal'!E33)
C25: =IF('Ber. st. 3'!B6=0,"",'Ber. st. 3'!B6) | E25: =IF('Ber. st. 3'!C6=0,"",'Ber. st. 3'!C6) | J25: =IF('Ber. st. 3'!D6=0,"",'Ber. st. 3'!D6) | N25: =IF('Ber. st. 3'!E6=0,"",'Ber. st. 3'!E6) | P25: =IF('Ber. st. 6'!B6=0,"",'Ber. st. 6'!B6) | R25: =IF('Ber. st. 6'!C6=0,"",'Ber. st. 6'!C6) | W25: =IF('Ber. st. 6'!D6=0,"",'Ber. st. 6'!D6) | AA25: =IF('Ber. st. 6'!E6=0,"",'Ber. st. 6'!E6) | AC25: =IF('Ber. st. 9'!B6=0,"",'Ber. st. 9'!B6) | AE25: =IF('Ber. st. 9'!C6=0,"",'Ber. st. 9'!C6) | AJ25: =IF('Ber. st. 9'!D6=0,"",'Ber. st. 9'!D6) | AN25: =IF('Ber. st. 9'!E6=0,"",'Ber. st. 9'!E6) | AR25: =IF('Ber. Hulpmateriaal'!B34=0,"",'Ber. Hulpmateriaal'!B34) | AT25: =IF('Ber. Hulpmateriaal'!C34=0,"",'Ber. Hulpmateriaal'!C34) | AY25: =IF('Ber. Hulpmateriaal'!D34=0,"",'Ber. Hulpmateriaal'!D34) | BC25: =IF('Ber. Hulpmateriaal'!E34=0,"",'Ber. Hulpmateriaal'!E34)
C26: =IF('Ber. st. 3'!B7=0,"",'Ber. st. 3'!B7) | E26: =IF('Ber. st. 3'!C7=0,"",'Ber. st. 3'!C7) | J26: =IF('Ber. st. 3'!D7=0,"",'Ber. st. 3'!D7) | N26: =IF('Ber. st. 3'!E7=0,"",'Ber. st. 3'!E7) | P26: =IF('Ber. st. 6'!B7=0,"",'Ber. st. 6'!B7) | R26: =IF('Ber. st. 6'!C7=0,"",'Ber. st. 6'!C7) | W26: =IF('Ber. st. 6'!D7=0,"",'Ber. st. 6'!D7) | AA26: =IF('Ber. st. 6'!E7=0,"",'Ber. st. 6'!E7) | AC26: =IF('Ber. st. 9'!B7=0,"",'Ber. st. 9'!B7) | AE26: =IF('Ber. st. 9'!C7=0,"",'Ber. st. 9'!C7) | AJ26: =IF('Ber. st. 9'!D7=0,"",'Ber. st. 9'!D7) | AN26: =IF('Ber. st. 9'!E7=0,"",'Ber. st. 9'!E7)
C27: =IF('Ber. st. 3'!B8=0,"",'Ber. st. 3'!B8) | E27: =IF('Ber. st. 3'!C8=0,"",'Ber. st. 3'!C8) | J27: =IF('Ber. st. 3'!D8=0,"",'Ber. st. 3'!D8) | N27: =IF('Ber. st. 3'!E8=0,"",'Ber. st. 3'!E8) | P27: =IF('Ber. st. 6'!B8=0,"",'Ber. st. 6'!B8) | R27: =IF('Ber. st. 6'!C8=0,"",'Ber. st. 6'!C8) | W27: =IF('Ber. st. 6'!D8=0,"",'Ber. st. 6'!D8) | AA27: =IF('Ber. st. 6'!E8=0,"",'Ber. st. 6'!E8) | AC27: =IF('Ber. st. 9'!B8=0,"",'Ber. st. 9'!B8) | AE27: =IF('Ber. st. 9'!C8=0,"",'Ber. st. 9'!C8) | AJ27: =IF('Ber. st. 9'!D8=0,"",'Ber. st. 9'!D8) | AN27: =IF('Ber. st. 9'!E8=0,"",'Ber. st. 9'!E8)
C28: =IF('Ber. st. 3'!B9=0,"",'Ber. st. 3'!B9) | E28: =IF('Ber. st. 3'!C9=0,"",'Ber. st. 3'!C9) | J28: =IF('Ber. st. 3'!D9=0,"",'Ber. st. 3'!D9) | N28: =IF('Ber. st. 3'!E9=0,"",'Ber. st. 3'!E9) | P28: =IF('Ber. st. 6'!B9=0,"",'Ber. st. 6'!B9) | R28: =IF('Ber. st. 6'!C9=0,"",'Ber. st. 6'!C9) | W28: =IF('Ber. st. 6'!D9=0,"",'Ber. st. 6'!D9) | AA28: =IF('Ber. st. 6'!E9=0,"",'Ber. st. 6'!E9) | AC28: =IF('Ber. st. 9'!B9=0,"",'Ber. st. 9'!B9) | AE28: =IF('Ber. st. 9'!C9=0,"",'Ber. st. 9'!C9) | AJ28: =IF('Ber. st. 9'!D9=0,"",'Ber. st. 9'!D9) | AN28: =IF('Ber. st. 9'!E9=0,"",'Ber. st. 9'!E9)
C29: =IF('Ber. st. 3'!B10=0,"",'Ber. st. 3'!B10) | E29: =IF('Ber. st. 3'!C10=0,"",'Ber. st. 3'!C10) | J29: =IF('Ber. st. 3'!D10=0,"",'Ber. st. 3'!D10) | N29: =IF('Ber. st. 3'!E10=0,"",'Ber. st. 3'!E10) | P29: =IF('Ber. st. 6'!B10=0,"",'Ber. st. 6'!B10) | R29: =IF('Ber. st. 6'!C10=0,"",'Ber. st. 6'!C10) | W29: =IF('Ber. st. 6'!D10=0,"",'Ber. st. 6'!D10) | AA29: =IF('Ber. st. 6'!E10=0,"",'Ber. st. 6'!E10) | AC29: =IF('Ber. st. 9'!B10=0,"",'Ber. st. 9'!B10) | AE29: =IF('Ber. st. 9'!C10=0,"",'Ber. st. 9'!C10) | AJ29: =IF('Ber. st. 9'!D10=0,"",'Ber. st. 9'!D10) | AN29: =IF('Ber. st. 9'!E10=0,"",'Ber. st. 9'!E10)
C32: Week: | E32: 9 | G32: Totale uren p. week: | K32: 200 | M32: Beschikbaar: | O32: =K32-SUM(Q34:Q58) -> 200 | S32: Week: | U32: =E32+1 -> 10 | W32: Totale uren p. week: | AA32: 200 | AC32: Beschikbaar: | AH32: =AA32-SUM(AI34:AJ58) -> 200 | AL32: Week: | AN32: =U32+1 -> 11 | AP32: Totale uren p. week: | AV32: 200 | AX32: Beschikbaar: | BA32: =AV32-SUM(BA34:BB58) -> 200
D33: Order | F33: Omschrijving | K33: Klant | N33: St. | O33: Uren | Q33: Tot. | T33: Order | V33: Omschrijving | AB33: Klant | AF33: St. | AH33: Uren | AI33: Tot. | AM33: Order | AO33: Omschrijving | AV33: Klant | AY33: St. | AZ33: Uren | BA33: Tot.
C34: Tomasz | D34: =IF('Ber. Planning Tomasz'!AF4="","",'Ber. Planning Tomasz'!AF4) | F34: =IF('Ber. Planning Tomasz'!AG4="","",'Ber. Planning Tomasz'!AG4) | K34: =IF('Ber. Planning Tomasz'!AH4="","",'Ber. Planning Tomasz'!AH4) | N34: =IF('Ber. Planning Tomasz'!AJ4="","",'Ber. Planning Tomasz'!AJ4) | O34: =IF('Ber. Planning Tomasz'!AI4="","",'Ber. Planning Tomasz'!AI4) | Q34: =SUM(O34:P38) -> 0 | R34: =IF(Q34<>'Ber. Planning Tomasz'!AI15,"!","") | S34: Dariusz | T34: =IF('Ber. Planning Tomasz'!AF19="","",'Ber. Planning Tomasz'!AF19) | V34: =IF('Ber. Planning Tomasz'!AG19="","",'Ber. Planning Tomasz'!AG19) | AB34: =IF('Ber. Planning Tomasz'!AH19="","",'Ber. Planning Tomasz'!AH19) | AF34: =IF('Ber. Planning Tomasz'!AJ19="","",'Ber. Planning Tomasz'!AJ19) | AH34: =IF('Ber. Planning Tomasz'!AI19="","",'Ber. Planning Tomasz'!AI19) | AI34: =SUM(AH34:AH38) -> 0 | AK34: =IF(AI34<>'Ber. Planning Tomasz'!AI30,"!","") | AL34: Dariusz | AM34: =IF('Ber. Planning Tomasz'!AF34="","",'Ber. Planning Tomasz'!AF34) | AO34: =IF('Ber. Planning Tomasz'!AG34="","",'Ber. Planning Tomasz'!AG34) | AV34: =IF('Ber. Planning Tomasz'!AH34="","",'Ber. Planning Tomasz'!AH34) | AY34: =IF('Ber. Planning Tomasz'!AJ34="","",'Ber. Planning Tomasz'!AJ34) | AZ34: =IF('Ber. Planning Tomasz'!AI34="","",'Ber. Planning Tomasz'!AI34) | BA34: =SUM(AZ34:AZ38) -> 0 | BC34: =IF(BA34<>'Ber. Planning Tomasz'!AI45,"!","")
D35: =IF('Ber. Planning Tomasz'!AF5="","",'Ber. Planning Tomasz'!AF5) | F35: =IF('Ber. Planning Tomasz'!AG5="","",'Ber. Planning Tomasz'!AG5) | K35: =IF('Ber. Planning Tomasz'!AH5="","",'Ber. Planning Tomasz'!AH5) | N35: =IF('Ber. Planning Tomasz'!AJ5="","",'Ber. Planning Tomasz'!AJ5) | O35: =IF('Ber. Planning Tomasz'!AI5="","",'Ber. Planning Tomasz'!AI5) | T35: =IF('Ber. Planning Tomasz'!AF20="","",'Ber. Planning Tomasz'!AF20) | V35: =IF('Ber. Planning Tomasz'!AG20="","",'Ber. Planning Tomasz'!AG20) | AB35: =IF('Ber. Planning Tomasz'!AH20="","",'Ber. Planning Tomasz'!AH20) | AF35: =IF('Ber. Planning Tomasz'!AJ20="","",'Ber. Planning Tomasz'!AJ20) | AH35: =IF('Ber. Planning Tomasz'!AI20="","",'Ber. Planning Tomasz'!AI20) | AM35: =IF('Ber. Planning Tomasz'!AF35="","",'Ber. Planning Tomasz'!AF35) | AO35: =IF('Ber. Planning Tomasz'!AG35="","",'Ber. Planning Tomasz'!AG35) | AV35: =IF('Ber. Planning Tomasz'!AH35="","",'Ber. Planning Tomasz'!AH35) | AY35: =IF('Ber. Planning Tomasz'!AJ35="","",'Ber. Planning Tomasz'!AJ35) | AZ35: =IF('Ber. Planning Tomasz'!AI35="","",'Ber. Planning Tomasz'!AI35)
D36: =IF('Ber. Planning Tomasz'!AF6="","",'Ber. Planning Tomasz'!AF6) | F36: =IF('Ber. Planning Tomasz'!AG6="","",'Ber. Planning Tomasz'!AG6) | K36: =IF('Ber. Planning Tomasz'!AH6="","",'Ber. Planning Tomasz'!AH6) | N36: =IF('Ber. Planning Tomasz'!AJ6="","",'Ber. Planning Tomasz'!AJ6) | O36: =IF('Ber. Planning Tomasz'!AI6="","",'Ber. Planning Tomasz'!AI6) | T36: =IF('Ber. Planning Tomasz'!AF21="","",'Ber. Planning Tomasz'!AF21) | V36: =IF('Ber. Planning Tomasz'!AG21="","",'Ber. Planning Tomasz'!AG21) | AB36: =IF('Ber. Planning Tomasz'!AH21="","",'Ber. Planning Tomasz'!AH21) | AF36: =IF('Ber. Planning Tomasz'!AJ21="","",'Ber. Planning Tomasz'!AJ21) | AH36: =IF('Ber. Planning Tomasz'!AI21="","",'Ber. Planning Tomasz'!AI21) | AM36: =IF('Ber. Planning Tomasz'!AF36="","",'Ber. Planning Tomasz'!AF36) | AO36: =IF('Ber. Planning Tomasz'!AG36="","",'Ber. Planning Tomasz'!AG36) | AV36: =IF('Ber. Planning Tomasz'!AH36="","",'Ber. Planning Tomasz'!AH36) | AY36: =IF('Ber. Planning Tomasz'!AJ36="","",'Ber. Planning Tomasz'!AJ36) | AZ36: =IF('Ber. Planning Tomasz'!AI36="","",'Ber. Planning Tomasz'!AI36)
D37: =IF('Ber. Planning Tomasz'!AF7="","",'Ber. Planning Tomasz'!AF7) | F37: =IF('Ber. Planning Tomasz'!AG7="","",'Ber. Planning Tomasz'!AG7) | K37: =IF('Ber. Planning Tomasz'!AH7="","",'Ber. Planning Tomasz'!AH7) | N37: =IF('Ber. Planning Tomasz'!AJ7="","",'Ber. Planning Tomasz'!AJ7) | O37: =IF('Ber. Planning Tomasz'!AI7="","",'Ber. Planning Tomasz'!AI7) | T37: =IF('Ber. Planning Tomasz'!AF22="","",'Ber. Planning Tomasz'!AF22) | V37: =IF('Ber. Planning Tomasz'!AG22="","",'Ber. Planning Tomasz'!AG22) | AB37: =IF('Ber. Planning Tomasz'!AH22="","",'Ber. Planning Tomasz'!AH22) | AF37: =IF('Ber. Planning Tomasz'!AJ22="","",'Ber. Planning Tomasz'!AJ22) | AH37: =IF('Ber. Planning Tomasz'!AI22="","",'Ber. Planning Tomasz'!AI22) | AM37: =IF('Ber. Planning Tomasz'!AF37="","",'Ber. Planning Tomasz'!AF37) | AO37: =IF('Ber. Planning Tomasz'!AG37="","",'Ber. Planning Tomasz'!AG37) | AV37: =IF('Ber. Planning Tomasz'!AH37="","",'Ber. Planning Tomasz'!AH37) | AY37: =IF('Ber. Planning Tomasz'!AJ37="","",'Ber. Planning Tomasz'!AJ37) | AZ37: =IF('Ber. Planning Tomasz'!AI37="","",'Ber. Planning Tomasz'!AI37)
D38: =IF('Ber. Planning Tomasz'!AF8="","",'Ber. Planning Tomasz'!AF8) | F38: =IF('Ber. Planning Tomasz'!AG8="","",'Ber. Planning Tomasz'!AG8) | K38: =IF('Ber. Planning Tomasz'!AH8="","",'Ber. Planning Tomasz'!AH8) | N38: =IF('Ber. Planning Tomasz'!AJ8="","",'Ber. Planning Tomasz'!AJ8) | O38: =IF('Ber. Planning Tomasz'!AI8="","",'Ber. Planning Tomasz'!AI8) | T38: =IF('Ber. Planning Tomasz'!AF23="","",'Ber. Planning Tomasz'!AF23) | V38: =IF('Ber. Planning Tomasz'!AG23="","",'Ber. Planning Tomasz'!AG23) | AB38: =IF('Ber. Planning Tomasz'!AH23="","",'Ber. Planning Tomasz'!AH23) | AF38: =IF('Ber. Planning Tomasz'!AJ23="","",'Ber. Planning Tomasz'!AJ23) | AH38: =IF('Ber. Planning Tomasz'!AI23="","",'Ber. Planning Tomasz'!AI23) | AM38: =IF('Ber. Planning Tomasz'!AF38="","",'Ber. Planning Tomasz'!AF38) | AO38: =IF('Ber. Planning Tomasz'!AG38="","",'Ber. Planning Tomasz'!AG38) | AV38: =IF('Ber. Planning Tomasz'!AH38="","",'Ber. Planning Tomasz'!AH38) | AY38: =IF('Ber. Planning Tomasz'!AJ38="","",'Ber. Planning Tomasz'!AJ38) | AZ38: =IF('Ber. Planning Tomasz'!AI38="","",'Ber. Planning Tomasz'!AI38)
C39: Ed | D39: =IF('Ber. Planning Ed'!AF$4="","",'Ber. Planning Ed'!AF$4) | F39: =IF('Ber. Planning Ed'!AG$4="","",'Ber. Planning Ed'!AG$4) | K39: =IF('Ber. Planning Ed'!AH$4="","",'Ber. Planning Ed'!AH$4) | N39: =IF('Ber. Planning Ed'!AJ$4="","",'Ber. Planning Ed'!AJ$4) | O39: =IF('Ber. Planning Ed'!AI$4="","",'Ber. Planning Ed'!AI$4) | Q39: =SUM(O39:P43) -> 0 | R39: =IF(Q39<>'Ber. Planning Ed'!AI15,"!","") | S39: Ed | T39: =IF('Ber. Planning Ed'!AF19="","",'Ber. Planning Ed'!AF19) | V39: =IF('Ber. Planning Ed'!AG19="","",'Ber. Planning Ed'!AG19) | AB39: =IF('Ber. Planning Ed'!AH19="","",'Ber. Planning Ed'!AH19) | AF39: =IF('Ber. Planning Ed'!AJ19="","",'Ber. Planning Ed'!AJ19) | AH39: =IF('Ber. Planning Ed'!AI19="","",'Ber. Planning Ed'!AI19) | AI39: =SUM(AH39:AH43) -> 0 | AK39: =IF(AI39<>'Ber. Planning Ed'!AI30,"!","") | AL39: Ed | AM39: =IF('Ber. Planning Ed'!AF34="","",'Ber. Planning Ed'!AF34) | AO39: =IF('Ber. Planning Ed'!AG34="","",'Ber. Planning Ed'!AG34) | AV39: =IF('Ber. Planning Ed'!AH34="","",'Ber. Planning Ed'!AH34) | AY39: =IF('Ber. Planning Ed'!AJ34="","",'Ber. Planning Ed'!AJ34) | AZ39: =IF('Ber. Planning Ed'!AI34="","",'Ber. Planning Ed'!AI34) | BA39: =SUM(AZ39:AZ43) -> 0 | BC39: =IF(BA39<>'Ber. Planning Ed'!AI45,"!","")
D40: =IF('Ber. Planning Ed'!AF5="","",'Ber. Planning Ed'!AF5) | F40: =IF('Ber. Planning Ed'!AG5="","",'Ber. Planning Ed'!AG5) | K40: =IF('Ber. Planning Ed'!AH5="","",'Ber. Planning Ed'!AH5) | N40: =IF('Ber. Planning Ed'!AJ5="","",'Ber. Planning Ed'!AJ5) | O40: =IF('Ber. Planning Ed'!AI5="","",'Ber. Planning Ed'!AI5) | T40: =IF('Ber. Planning Ed'!AF20="","",'Ber. Planning Ed'!AF20) | V40: =IF('Ber. Planning Ed'!AG20="","",'Ber. Planning Ed'!AG20) | AB40: =IF('Ber. Planning Ed'!AH20="","",'Ber. Planning Ed'!AH20) | AF40: =IF('Ber. Planning Ed'!AJ20="","",'Ber. Planning Ed'!AJ20) | AH40: =IF('Ber. Planning Ed'!AI20="","",'Ber. Planning Ed'!AI20) | AM40: =IF('Ber. Planning Ed'!AF35="","",'Ber. Planning Ed'!AF35) | AO40: =IF('Ber. Planning Ed'!AG35="","",'Ber. Planning Ed'!AG35) | AV40: =IF('Ber. Planning Ed'!AH35="","",'Ber. Planning Ed'!AH35) | AY40: =IF('Ber. Planning Ed'!AJ35="","",'Ber. Planning Ed'!AJ35) | AZ40: =IF('Ber. Planning Ed'!AI35="","",'Ber. Planning Ed'!AI35)
D41: =IF('Ber. Planning Ed'!AF6="","",'Ber. Planning Ed'!AF6) | F41: =IF('Ber. Planning Ed'!AG6="","",'Ber. Planning Ed'!AG6) | K41: =IF('Ber. Planning Ed'!AH6="","",'Ber. Planning Ed'!AH6) | N41: =IF('Ber. Planning Ed'!AJ6="","",'Ber. Planning Ed'!AJ6) | O41: =IF('Ber. Planning Ed'!AI6="","",'Ber. Planning Ed'!AI6) | T41: =IF('Ber. Planning Ed'!AF21="","",'Ber. Planning Ed'!AF21) | V41: =IF('Ber. Planning Ed'!AG21="","",'Ber. Planning Ed'!AG21) | AB41: =IF('Ber. Planning Ed'!AH21="","",'Ber. Planning Ed'!AH21) | AF41: =IF('Ber. Planning Ed'!AJ21="","",'Ber. Planning Ed'!AJ21) | AH41: =IF('Ber. Planning Ed'!AI21="","",'Ber. Planning Ed'!AI21) | AM41: =IF('Ber. Planning Ed'!AF36="","",'Ber. Planning Ed'!AF36) | AO41: =IF('Ber. Planning Ed'!AG36="","",'Ber. Planning Ed'!AG36) | AV41: =IF('Ber. Planning Ed'!AH36="","",'Ber. Planning Ed'!AH36) | AY41: =IF('Ber. Planning Ed'!AJ36="","",'Ber. Planning Ed'!AJ36) | AZ41: =IF('Ber. Planning Ed'!AI36="","",'Ber. Planning Ed'!AI36)
D42: =IF('Ber. Planning Ed'!AF7="","",'Ber. Planning Ed'!AF7) | F42: =IF('Ber. Planning Ed'!AG7="","",'Ber. Planning Ed'!AG7) | K42: =IF('Ber. Planning Ed'!AH7="","",'Ber. Planning Ed'!AH7) | N42: =IF('Ber. Planning Ed'!AJ7="","",'Ber. Planning Ed'!AJ7) | O42: =IF('Ber. Planning Ed'!AI7="","",'Ber. Planning Ed'!AI7) | T42: =IF('Ber. Planning Ed'!AF22="","",'Ber. Planning Ed'!AF22) | V42: =IF('Ber. Planning Ed'!AG22="","",'Ber. Planning Ed'!AG22) | AB42: =IF('Ber. Planning Ed'!AH22="","",'Ber. Planning Ed'!AH22) | AF42: =IF('Ber. Planning Ed'!AJ22="","",'Ber. Planning Ed'!AJ22) | AH42: =IF('Ber. Planning Ed'!AI22="","",'Ber. Planning Ed'!AI22) | AM42: =IF('Ber. Planning Ed'!AF37="","",'Ber. Planning Ed'!AF37) | AO42: =IF('Ber. Planning Ed'!AG37="","",'Ber. Planning Ed'!AG37) | AV42: =IF('Ber. Planning Ed'!AH37="","",'Ber. Planning Ed'!AH37) | AY42: =IF('Ber. Planning Ed'!AJ37="","",'Ber. Planning Ed'!AJ37) | AZ42: =IF('Ber. Planning Ed'!AI37="","",'Ber. Planning Ed'!AI37)
D43: =IF('Ber. Planning Ed'!AF8="","",'Ber. Planning Ed'!AF8) | F43: =IF('Ber. Planning Ed'!AG8="","",'Ber. Planning Ed'!AG8) | K43: =IF('Ber. Planning Ed'!AH8="","",'Ber. Planning Ed'!AH8) | N43: =IF('Ber. Planning Ed'!AJ8="","",'Ber. Planning Ed'!AJ8) | O43: =IF('Ber. Planning Ed'!AI8="","",'Ber. Planning Ed'!AI8) | T43: =IF('Ber. Planning Ed'!AF23="","",'Ber. Planning Ed'!AF23) | V43: =IF('Ber. Planning Ed'!AG23="","",'Ber. Planning Ed'!AG23) | AB43: =IF('Ber. Planning Ed'!AH23="","",'Ber. Planning Ed'!AH23) | AF43: =IF('Ber. Planning Ed'!AJ23="","",'Ber. Planning Ed'!AJ23) | AH43: =IF('Ber. Planning Ed'!AI23="","",'Ber. Planning Ed'!AI23) | AM43: =IF('Ber. Planning Ed'!AF38="","",'Ber. Planning Ed'!AF38) | AO43: =IF('Ber. Planning Ed'!AG38="","",'Ber. Planning Ed'!AG38) | AV43: =IF('Ber. Planning Ed'!AH38="","",'Ber. Planning Ed'!AH38) | AY43: =IF('Ber. Planning Ed'!AJ38="","",'Ber. Planning Ed'!AJ38) | AZ43: =IF('Ber. Planning Ed'!AI38="","",'Ber. Planning Ed'!AI38)
...

Sheet Uitbesteed
B2: Uitbesteed
C3: UITBESTEED
C4: Ordernummer | E4: Omschrijving | H4: Klant | J4: Week
C5: =IFERROR(IF('Ber. Uitbesteed'!B4=0,"",'Ber. Uitbesteed'!B4),"") | E5: =IF('Ber. Uitbesteed'!C4=0,"",'Ber. Uitbesteed'!C4) | H5: =IF('Ber. Uitbesteed'!D4=0,"",'Ber. Uitbesteed'!D4) | J5: =IF('Ber. Uitbesteed'!E4=0,"",'Ber. Uitbesteed'!E4)
C6: =IFERROR(IF('Ber. Uitbesteed'!B5=0,"",'Ber. Uitbesteed'!B5),"") | E6: =IF('Ber. Uitbesteed'!C5=0,"",'Ber. Uitbesteed'!C5) | H6: =IF('Ber. Uitbesteed'!D5=0,"",'Ber. Uitbesteed'!D5) | J6: =IF('Ber. Uitbesteed'!E5=0,"",'Ber. Uitbesteed'!E5)
C7: =IFERROR(IF('Ber. Uitbesteed'!B6=0,"",'Ber. Uitbesteed'!B6),"") | E7: =IF('Ber. Uitbesteed'!C6=0,"",'Ber. Uitbesteed'!C6) | H7: =IF('Ber. Uitbesteed'!D6=0,"",'Ber. Uitbesteed'!D6) | J7: =IF('Ber. Uitbesteed'!E6=0,"",'Ber. Uitbesteed'!E6)
C8: =IFERROR(IF('Ber. Uitbesteed'!B7=0,"",'Ber. Uitbesteed'!B7),"") | E8: =IF('Ber. Uitbesteed'!C7=0,"",'Ber. Uitbesteed'!C7) | H8: =IF('Ber. Uitbesteed'!D7=0,"",'Ber. Uitbesteed'!D7) | J8: =IF('Ber. Uitbesteed'!E7=0,"",'Ber. Uitbesteed'!E7)
C9: =IFERROR(IF('Ber. Uitbesteed'!B8=0,"",'Ber. Uitbesteed'!B8),"") | E9: =IF('Ber. Uitbesteed'!C8=0,"",'Ber. Uitbesteed'!C8) | H9: =IF('Ber. Uitbesteed'!D8=0,"",'Ber. Uitbesteed'!D8) | J9: =IF('Ber. Uitbesteed'!E8=0,"",'Ber. Uitbesteed'!E8)
C10: =IFERROR(IF('Ber. Uitbesteed'!B9=0,"",'Ber. Uitbesteed'!B9),"") | E10: =IF('Ber. Uitbesteed'!C9=0,"",'Ber. Uitbesteed'!C9) | H10: =IF('Ber. Uitbesteed'!D9=0,"",'Ber. Uitbesteed'!D9) | J10: =IF('Ber. Uitbesteed'!E9=0,"",'Ber. Uitbesteed'!E9)
C11: =IFERROR(IF('Ber. Uitbesteed'!B10=0,"",'Ber. Uitbesteed'!B10),"") | E11: =IF('Ber. Uitbesteed'!C10=0,"",'Ber. Uitbesteed'!C10) | H11: =IF('Ber. Uitbesteed'!D10=0,"",'Ber. Uitbesteed'!D10) | J11: =IF('Ber. Uitbesteed'!E10=0,"",'Ber. Uitbesteed'!E10)
C12: =IFERROR(IF('Ber. Uitbesteed'!B11=0,"",'Ber. Uitbesteed'!B11),"") | E12: =IF('Ber. Uitbesteed'!C11=0,"",'Ber. Uitbesteed'!C11) | H12: =IF('Ber. Uitbesteed'!D11=0,"",'Ber. Uitbesteed'!D11) | J12: =IF('Ber. Uitbesteed'!E11=0,"",'Ber. Uitbesteed'!E11)
C13: =IFERROR(IF('Ber. Uitbesteed'!B12=0,"",'Ber. Uitbesteed'!B12),"") | E13: =IF('Ber. Uitbesteed'!C12=0,"",'Ber. Uitbesteed'!C12) | H13: =IF('Ber. Uitbesteed'!D12=0,"",'Ber. Uitbesteed'!D12) | J13: =IF('Ber. Uitbesteed'!E12=0,"",'Ber. Uitbesteed'!E12)
C14: =IFERROR(IF('Ber. Uitbesteed'!B13=0,"",'Ber. Uitbesteed'!B13),"") | E14: =IF('Ber. Uitbesteed'!C13=0,"",'Ber. Uitbesteed'!C13) | H14: =IF('Ber. Uitbesteed'!D13=0,"",'Ber. Uitbesteed'!D13) | J14: =IF('Ber. Uitbesteed'!E13=0,"",'Ber. Uitbesteed'!E13)
C15: =IFERROR(IF('Ber. Uitbesteed'!B14=0,"",'Ber. Uitbesteed'!B14),"") | E15: =IF('Ber. Uitbesteed'!C14=0,"",'Ber. Uitbesteed'!C14) | H15: =IF('Ber. Uitbesteed'!D14=0,"",'Ber. Uitbesteed'!D14) | J15: =IF('Ber. Uitbesteed'!E14=0,"",'Ber. Uitbesteed'!E14)
C16: =IFERROR(IF('Ber. Uitbesteed'!B15=0,"",'Ber. Uitbesteed'!B15),"") | E16: =IF('Ber. Uitbesteed'!C15=0,"",'Ber. Uitbesteed'!C15) | H16: =IF('Ber. Uitbesteed'!D15=0,"",'Ber. Uitbesteed'!D15) | J16: =IF('Ber. Uitbesteed'!E15=0,"",'Ber. Uitbesteed'!E15)
... C30: =IFERROR(IF('Ber. Uitbesteed'!B29=0,"",'Ber. Uitbesteed'!B29),"") | E30: =IF('Ber. Uitbesteed'!C29=0,"",'Ber. Uitbesteed'!C29) | H30: =IF('Ber. Uitbesteed'!D29=0,"",'Ber. Uitbesteed'!D29) | J30: =IF('Ber. Uitbesteed'!E29=0,"",'Ber. Uitbesteed'!E29)

Sheet Invulmogelijkheden
B2: Invulmogelijkheden:
B3: Week | C3: Medewerker: | D3: Status: | E3: Hulpmaterialen:
B5: 1 | C5: Tomasz | D5: 1 - Werkvoorbereiding | E5: 0 - Niet nodig
B6: 2 | C6: Ed | D6: 2 - Materiaal deels besteld | E6: 1 - Nog bestellen
B7: 3 | C7: Tomasz F | D7: 3 - Materiaal besteld | E7: 2 - Besteld
B8: 4 | C8: Mark | D8: 4 - Materiaal binnen | E8: 3 - Compleet
B9: 5 | C9: Zoltan | D9: 5 - Voorbereiden (Nobelweg 2B) | E9: 4 - Afgeleverd
B10: 6 | C10: Voorbewerking | D10: 6 - In productie (Nobelweg 3) | I10: Tomasz, Ed, Tomasz F, Mark, Zoltan, Voorbewerking
B11: 7 | C11: Overig | D11: 7 - Klaar voor coater/verzinkerij
B12: 8 | D12: 8 - Bij coater/verzinkerij
B13: 9 | D13: 9 - Gereed, kan worden opgehaald
B14: 10 | D14: 10 - Afgeleverd
B15: 11 | D15: UITBESTEED
B16: 12
B17: 13
B18: 14
B19: 15
B20: 16
B21: 17
B22: 18
B23: 19
B24: 20
B25: 21
B26: 22
B27: 23
... B56: 52

Sheet Ber. st. 1
B2: 1 - Werkvoorbereiding
B3: Ordernummer: | C3: Omschrijving: | D3: Klant: | E3: Week: | F3: Totale uren: | G3: Medewerker 1: | H3: % uren 1: | I3: Uren 1: | J3: Medewerker 2: | K3: % uren 2: | L3: Uren 2: | M3: Status: | N3: Hulpmaterialen:
B4: {=_xlfn._xlws.SORT(_xlfn._xlws.FILTER(Invulblad!B6:T1003,Invulblad!S6:S1003=B2,""),4,1)} -> #VALUE!

Sheet Ber. st. 2
B2: 2 - Materiaal deels besteld
B3: Ordernummer: | C3: Omschrijving: | D3: Klant: | E3: Week: | F3: Totale uren: | G3: Medewerker 1: | H3: % uren 1: | I3: Uren 1: | J3: Medewerker 2: | K3: % uren 2: | L3: Uren 2: | M3: Status: | N3: Hulpmaterialen:
B4: {=_xlfn._xlws.SORT(_xlfn._xlws.FILTER(Invulblad!B6:T1003,Invulblad!S6:S1003=B2,""),4,1)} -> #VALUE!

Sheet Ber. st. 3
B2: 3 - Materiaal besteld
B3: Ordernummer: | C3: Omschrijving: | D3: Klant: | E3: Week: | F3: Totale uren: | G3: Medewerker 1: | H3: % uren 1: | I3: Uren 1: | J3: Medewerker 2: | K3: % uren 2: | L3: Uren 2: | M3: Status: | N3: Hulpmaterialen:
B4: {=_xlfn._xlws.SORT(_xlfn._xlws.FILTER(Invulblad!B6:T1003,Invulblad!S6:S1003=B2,""),4,1)} -> #VALUE!

Sheet Ber. st. 4
B2: 4 - Materiaal binnen
B3: Ordernummer: | C3: Omschrijving: | D3: Klant: | E3: Week: | F3: Totale uren: | G3: Medewerker 1: | H3: % uren 1: | I3: Uren 1: | J3: Medewerker 2: | K3: % uren 2: | L3: Uren 2: | M3: Status: | N3: Hulpmaterialen:
B4: {=_xlfn._xlws.SORT(_xlfn._xlws.FILTER(Invulblad!B6:T1003,Invulblad!S6:S1003=B2,""),4,1)} -> #VALUE!

Sheet Ber. st. 5
B2: 5 - Voorbereiden (Nobelweg 2B)
B3: Ordernummer: | C3: Omschrijving: | D3: Klant: | E3: Week: | F3: Totale uren: | G3: Medewerker 1: | H3: % uren 1: | I3: Uren 1: | J3: Medewerker 2: | K3: % uren 2: | L3: Uren 2: | M3: Status: | N3: Hulpmaterialen:
B4: {=_xlfn._xlws.SORT(_xlfn._xlws.FILTER(Invulblad!B6:T1003,Invulblad!S6:S1003=B2,""),4,1)} -> #VALUE!

Sheet Ber. st. 6
B2: 6 - In productie (Nobelweg 3)
B3: Ordernummer: | C3: Omschrijving: | D3: Klant: | E3: Week: | F3: Totale uren: | G3: Medewerker 1: | H3: % uren 1: | I3: Uren 1: | J3: Medewerker 2: | K3: % uren 2: | L3: Uren 2: | M3: Status: | N3: Hulpmaterialen:
B4: {=_xlfn._xlws.SORT(_xlfn._xlws.FILTER(Invulblad!B6:T1003,Invulblad!S6:S1003=B2,""),4,1)} -> #VALUE!

Sheet Ber. st. 7
B2: 7 - Klaar voor coater/verzinkerij
B3: Ordernummer: | C3: Omschrijving: | D3: Klant: | E3: Week: | F3: Totale uren: | G3: Medewerker 1: | H3: % uren 1: | I3: Uren 1: | J3: Medewerker 2: | K3: % uren 2: | L3: Uren 2: | M3: Status: | N3: Hulpmaterialen:
B4: {=_xlfn._xlws.SORT(_xlfn._xlws.FILTER(Invulblad!B6:T1003,Invulblad!S6:S1003=B2,""),4,1)} -> #VALUE!

Sheet Ber. st. 8
B2: 8 - Bij coater/verzinkerij
B3: Ordernummer: | C3: Omschrijving: | D3: Klant: | E3: Week: | F3: Totale uren: | G3: Medewerker 1: | H3: % uren 1: | I3: Uren 1: | J3: Medewerker 2: | K3: % uren 2: | L3: Uren 2: | M3: Status: | N3: Hulpmaterialen:
B4: {=_xlfn._xlws.SORT(_xlfn._xlws.FILTER(Invulblad!B6:T1003,Invulblad!S6:S1003=B2,""),4,1)} -> #VALUE!

Sheet Ber. st. 9
B2: 9 - Gereed, kan worden opgehaald
B3: Ordernummer: | C3: Omschrijving: | D3: Klant: | E3: Week: | F3: Totale uren: | G3: Medewerker 1: | H3: % uren 1: | I3: Uren 1: | J3: Medewerker 2: | K3: % uren 2: | L3: Uren 2: | M3: Status: | N3: Hulpmaterialen:
B4: {=_xlfn._xlws.SORT(_xlfn._xlws.FILTER(Invulblad!B6:T1003,Invulblad!S6:S1003=B2,""),4,1)} -> #VALUE!

Sheet Ber. Uitbesteed
B2: UITBESTEED
B3: Ordernummer: | C3: Omschrijving: | D3: Klant: | E3: Week: | F3: Totale uren: | G3: Medewerker 1: | H3: % uren 1: | I3: Uren 1: | J3: Medewerker 2: | K3: % uren 2: | L3: Uren 2: | M3: Status: | N3: Hulpmaterialen:
B4: {=_xlfn._xlws.SORT(_xlfn._xlws.FILTER(Invulblad!B6:T1003,Invulblad!S6:S1003=B2,""),4,1)} -> #VALUE!

Sheet Ber. Hulpmateriaal
B2: 1 - Nog bestellen
B3: Ordernummer: | C3: Omschrijving: | D3: Klant: | E3: Week: | F3: Totale uren: | G3: Medewerker 1: | H3: % uren 1: | I3: Uren 1: | J3: Medewerker 2: | K3: % uren 2: | L3: Uren 2: | M3: Status: | N3: Hulpmaterialen:
B4: {=_xlfn._xlws.SORT(_xlfn._xlws.FILTER(Invulblad!B6:T1003,Invulblad!T6:T1003=B2,""),4,1)} -> #VALUE!
B15: 2 - Besteld
B16: Ordernummer: | C16: Omschrijving: | D16: Klant: | E16: Week: | F16: Totale uren: | G16: Medewerker 1: | H16: % uren 1: | I16: Uren 1: | J16: Medewerker 2: | K16: % uren 2: | L16: Uren 2: | M16: Status: | N16: Hulpmaterialen:
B17: {=_xlfn._xlws.SORT(_xlfn._xlws.FILTER(Invulblad!B6:T1003,Invulblad!T6:T1003=B15,""),4,1)} -> #VALUE!
B28: 3 - Compleet
B29: Ordernummer: | C29: Omschrijving: | D29: Klant: | E29: Week: | F29: Totale uren: | G29: Medewerker 1: | H29: % uren 1: | I29: Uren 1: | J29: Medewerker 2: | K29: % uren 2: | L29: Uren 2: | M29: Status: | N29: Hulpmaterialen:
B30: {=_xlfn._xlws.SORT(_xlfn._xlws.FILTER(Invulblad!B6:T1003,Invulblad!T6:T1003=B28,""),4,1)} -> #VALUE!

Sheet Ber. Planning Totaal
B2: Planning
B3: Ordernummer: | C3: Omschrijving: | D3: Klant: | E3: Week: | F3: Totale uren: | G3: Medewerker 1: | H3: % uren 1: | I3: Uren 1: | J3: Medewerker 2: | K3: % uren 2: | L3: Uren 2: | M3: Medewerker 3: | N3: % uren 3: | O3: Uren 3: | P3: Controle % | Q3: Datum coater/verzinkerij: | R3: Datum gereed: | S3: Status: | T3: Hulpmaterialen:
B4: {=_xlfn._xlws.SORT(_xlfn._xlws.FILTER(Invulblad!B6:T1003,Invulblad!S6:S1003<>"10 - Afgeleverd",""),4,1)} -> 0 | C4: 0 | D4: 0 | E4: 0 | F4: 0 | G4: 0 | H4: 0 | J4: 0 | K4: 0 | M4: 0 | N4: 0 | Q4: 0 | R4: 0 | S4: 0 | T4: 0
B5: 0 | C5: 0 | D5: 0 | E5: 0 | F5: 0 | G5: 0 | H5: 0 | J5: 0 | K5: 0 | M5: 0 | N5: 0 | Q5: 0 | R5: 0 | S5: 0 | T5: 0
B6: 0 | C6: 0 | D6: 0 | E6: 0 | F6: 0 | G6: 0 | H6: 0 | J6: 0 | K6: 0 | M6: 0 | N6: 0 | Q6: 0 | R6: 0 | S6: 0 | T6: 0
B7: 0 | C7: 0 | D7: 0 | E7: 0 | F7: 0 | G7: 0 | H7: 0 | J7: 0 | K7: 0 | M7: 0 | N7: 0 | Q7: 0 | R7: 0 | S7: 0 | T7: 0
B8: 0 | C8: 0 | D8: 0 | E8: 0 | F8: 0 | G8: 0 | H8: 0 | J8: 0 | K8: 0 | M8: 0 | N8: 0 | Q8: 0 | R8: 0 | S8: 0 | T8: 0
B9: 0 | C9: 0 | D9: 0 | E9: 0 | F9: 0 | G9: 0 | H9: 0 | J9: 0 | K9: 0 | M9: 0 | N9: 0 | Q9: 0 | R9: 0 | S9: 0 | T9: 0
B10: 0 | C10: 0 | D10: 0 | E10: 0 | F10: 0 | G10: 0 | H10: 0 | J10: 0 | K10: 0 | M10: 0 | N10: 0 | Q10: 0 | R10: 0 | S10: 0 | T10: 0
B11: 0 | C11: 0 | D11: 0 | E11: 0 | F11: 0 | G11: 0 | H11: 0 | J11: 0 | K11: 0 | M11: 0 | N11: 0 | Q11: 0 | R11: 0 | S11: 0 | T11: 0
B12: 0 | C12: 0 | D12: 0 | E12: 0 | F12: 0 | G12: 0 | H12: 0 | J12: 0 | K12: 0 | M12: 0 | N12: 0 | Q12: 0 | R12: 0 | S12: 0 | T12: 0
B13: 0 | C13: 0 | D13: 0 | E13: 0 | F13: 0 | G13: 0 | H13: 0 | J13: 0 | K13: 0 | M13: 0 | N13: 0 | Q13: 0 | R13: 0 | S13: 0 | T13: 0
B14: 0 | C14: 0 | D14: 0 | E14: 0 | F14: 0 | G14: 0 | H14: 0 | J14: 0 | K14: 0 | M14: 0 | N14: 0 | Q14: 0 | R14: 0 | S14: 0 | T14: 0
B15: 0 | C15: 0 | D15: 0 | E15: 0 | F15: 0 | G15: 0 | H15: 0 | J15: 0 | K15: 0 | M15: 0 | N15: 0 | Q15: 0 | R15: 0 | S15: 0 | T15: 0
B16: 0 | C16: 0 | D16: 0 | E16: 0 | F16: 0 | G16: 0 | H16: 0 | J16: 0 | K16: 0 | M16: 0 | N16: 0 | Q16: 0 | R16: 0 | S16: 0 | T16: 0
... B1001: 0 | C1001: 0 | D1001: 0 | E1001: 0 | F1001: 0 | G1001: 0 | H1001: 0 | J1001: 0 | K1001: 0 | M1001: 0 | N1001: 0 | Q1001: 0 | R1001: 0 | S1001: 0 | T1001: 0

Sheet Ber. Planning Tomasz
B2: Medewerker: | C2: Tomasz | AC2: Omrekening status: | AF2: Week: | AG2: =Dashboard!E32 -> 9
B3: Ordernummer: | C3: Omschrijving: | D3: Klant: | E3: Week: | F3: Totale uren: | G3: Medewerker 1: | H3: % uren 1: | I3: Uren 1: | J3: Medewerker 2: | K3: % uren 2: | L3: Uren 2: | M3: Medewerker 3: | N3: % uren 3: | O3: Uren 3: | P3: Controle % | Q3: Datum coater/verzinkerij: | R3: Datum gereed: | S3: Status: | T3: Hulpmaterialen: | V3: Week: | W3: Order: | X3: Omschrijving | Y3: Klant: | Z3: Uren: | AA3: Status: | AC3: Status: | AD3: Nummer: | AF3: Order: | AG3: Omschrijving | AH3: Klant: | AI3: Uren: | AJ3: Status:
B4: {=_xlfn._xlws.FILTER('Ber. Planning Totaal'!B4:T1000,('Ber. Planning Totaal'!G4:G1000=C2)+('Ber. Planning Totaal'!J4:J1000=C2)+('Ber. Planning Totaal'!M4:M1000=C2))} -> #VALUE! | V4: =IF(E4="","",E4) | W4: =IF(B4="","",B4) -> #VALUE! | X4: =IF(B4="","",C4) -> #VALUE! | Y4: =IF(B4="","",D4) -> #VALUE! | Z4: =IF(B4="","",IF(G4=$C$2,I4,L4)) -> #VALUE! | AA4: =IF(B4="","",VLOOKUP(S4,$AC$3:$AD$14,2,FALSE)) -> #VALUE! | AC4: 1 - Werkvoorbereiding | AD4: 1 | AF4: {=_xlfn._xlws.FILTER($W$4:$AA$100,$V$4:$V$100=AG2,"")}
V5: =IF(E5="","",E5) | W5: =IF(B5="","",B5) | X5: =IF(B5="","",C5) | Y5: =IF(B5="","",D5) | Z5: =IF(B5="","",IF(G5=$C$2,I5,L5)) | AA5: =IF(B5="","",VLOOKUP(S5,$AC$3:$AD$14,2,FALSE)) | AC5: 2 - Materiaal deels besteld | AD5: 2
V6: =IF(E6="","",E6) | W6: =IF(B6="","",B6) | X6: =IF(B6="","",C6) | Y6: =IF(B6="","",D6) | Z6: =IF(B6="","",IF(G6=$C$2,I6,L6)) | AA6: =IF(B6="","",VLOOKUP(S6,$AC$3:$AD$14,2,FALSE)) | AC6: 3 - Materiaal besteld | AD6: 3
V7: =IF(E7="","",E7) | W7: =IF(B7="","",B7) | X7: =IF(B7="","",C7) | Y7: =IF(B7="","",D7) | Z7: =IF(B7="","",IF(G7=$C$2,I7,L7)) | AA7: =IF(B7="","",VLOOKUP(S7,$AC$3:$AD$14,2,FALSE)) | AC7: 4 - Materiaal binnen | AD7: 4
V8: =IF(E8="","",E8) | W8: =IF(B8="","",B8) | X8: =IF(B8="","",C8) | Y8: =IF(B8="","",D8) | Z8: =IF(B8="","",IF(G8=$C$2,I8,L8)) | AA8: =IF(B8="","",VLOOKUP(S8,$AC$3:$AD$14,2,FALSE)) | AC8: 5 - Voorbereiden (Nobelweg 2B) | AD8: 5
V9: =IF(E9="","",E9) | W9: =IF(B9="","",B9) | X9: =IF(B9="","",C9) | Y9: =IF(B9="","",D9) | Z9: =IF(B9="","",IF(G9=$C$2,I9,L9)) | AA9: =IF(B9="","",VLOOKUP(S9,$AC$3:$AD$14,2,FALSE)) | AC9: 6 - In productie (Nobelweg 3) | AD9: 6
V10: =IF(E10="","",E10) | W10: =IF(B10="","",B10) | X10: =IF(B10="","",C10) | Y10: =IF(B10="","",D10) | Z10: =IF(B10="","",IF(G10=$C$2,I10,L10)) | AA10: =IF(B10="","",VLOOKUP(S10,$AC$3:$AD$14,2,FALSE)) | AC10: 7 - Klaar voor coater/verzinkerij | AD10: 7
V11: =IF(E11="","",E11) | W11: =IF(B11="","",B11) | X11: =IF(B11="","",C11) | Y11: =IF(B11="","",D11) | Z11: =IF(B11="","",IF(G11=$C$2,I11,L11)) | AA11: =IF(B11="","",VLOOKUP(S11,$AC$3:$AD$14,2,FALSE)) | AC11: 8 - Bij coater/verzinkerij | AD11: 8
V12: =IF(E12="","",E12) | W12: =IF(B12="","",B12) | X12: =IF(B12="","",C12) | Y12: =IF(B12="","",D12) | Z12: =IF(B12="","",IF(G12=$C$2,I12,L12)) | AA12: =IF(B12="","",VLOOKUP(S12,$AC$3:$AD$14,2,FALSE)) | AC12: 9 - Gereed, kan worden opgehaald | AD12: 9
V13: =IF(E13="","",E13) | W13: =IF(B13="","",B13) | X13: =IF(B13="","",C13) | Y13: =IF(B13="","",D13) | Z13: =IF(B13="","",IF(G13=$C$2,I13,L13)) | AA13: =IF(B13="","",VLOOKUP(S13,$AC$3:$AD$14,2,FALSE)) | AC13: 10 - Afgeleverd | AD13: 10
V14: =IF(E14="","",E14) | W14: =IF(B14="","",B14) | X14: =IF(B14="","",C14) | Y14: =IF(B14="","",D14) | Z14: =IF(B14="","",IF(G14=$C$2,I14,L14)) | AA14: =IF(B14="","",VLOOKUP(S14,$AC$3:$AD$14,2,FALSE)) | AC14: UITBESTEED | AD14: U
V15: =IF(E15="","",E15) | W15: =IF(B15="","",B15) | X15: =IF(B15="","",C15) | Y15: =IF(B15="","",D15) | Z15: =IF(B15="","",IF(G15=$C$2,I15,L15)) | AA15: =IF(B15="","",VLOOKUP(S15,$AC$3:$AD$14,2,FALSE)) | AF15: Totaal | AI15: =SUM(AI4:AI14) -> 0
V16: =IF(E16="","",E16) | W16: =IF(B16="","",B16) | X16: =IF(B16="","",C16) | Y16: =IF(B16="","",D16) | Z16: =IF(B16="","",IF(G16=$C$2,I16,L16)) | AA16: =IF(B16="","",VLOOKUP(S16,$AC$3:$AD$14,2,FALSE))
V17: =IF(E17="","",E17) | W17: =IF(B17="","",B17) | X17: =IF(B17="","",C17) | Y17: =IF(B17="","",D17) | Z17: =IF(B17="","",IF(G17=$C$2,I17,L17)) | AA17: =IF(B17="","",VLOOKUP(S17,$AC$3:$AD$14,2,FALSE)) | AF17: Week: | AG17: =Dashboard!U32 -> 10
V18: =IF(E18="","",E18) | W18: =IF(B18="","",B18) | X18: =IF(B18="","",C18) | Y18: =IF(B18="","",D18) | Z18: =IF(B18="","",IF(G18=$C$2,I18,L18)) | AA18: =IF(B18="","",VLOOKUP(S18,$AC$3:$AD$14,2,FALSE)) | AF18: Order: | AG18: Omschrijving | AH18: Klant: | AI18: Uren: | AJ18: Status:
V19: =IF(E19="","",E19) | W19: =IF(B19="","",B19) | X19: =IF(B19="","",C19) | Y19: =IF(B19="","",D19) | Z19: =IF(B19="","",IF(G19=$C$2,I19,L19)) | AA19: =IF(B19="","",VLOOKUP(S19,$AC$3:$AD$14,2,FALSE)) | AF19: {=_xlfn._xlws.FILTER($W$4:$AA$100,$V$4:$V$100=AG17,"")}
V20: =IF(E20="","",E20) | W20: =IF(B20="","",B20) | X20: =IF(B20="","",C20) | Y20: =IF(B20="","",D20) | Z20: =IF(B20="","",IF(G20=$C$2,I20,L20)) | AA20: =IF(B20="","",VLOOKUP(S20,$AC$3:$AD$14,2,FALSE))
V21: =IF(E21="","",E21) | W21: =IF(B21="","",B21) | X21: =IF(B21="","",C21) | Y21: =IF(B21="","",D21) | Z21: =IF(B21="","",IF(G21=$C$2,I21,L21)) | AA21: =IF(B21="","",VLOOKUP(S21,$AC$3:$AD$14,2,FALSE))
V22: =IF(E22="","",E22) | W22: =IF(B22="","",B22) | X22: =IF(B22="","",C22) | Y22: =IF(B22="","",D22) | Z22: =IF(B22="","",IF(G22=$C$2,I22,L22)) | AA22: =IF(B22="","",VLOOKUP(S22,$AC$3:$AD$14,2,FALSE))
V23: =IF(E23="","",E23) | W23: =IF(B23="","",B23) | X23: =IF(B23="","",C23) | Y23: =IF(B23="","",D23) | Z23: =IF(B23="","",IF(G23=$C$2,I23,L23)) | AA23: =IF(B23="","",VLOOKUP(S23,$AC$3:$AD$14,2,FALSE))
V24: =IF(E24="","",E24) | W24: =IF(B24="","",B24) | X24: =IF(B24="","",C24) | Y24: =IF(B24="","",D24) | Z24: =IF(B24="","",IF(G24=$C$2,I24,L24)) | AA24: =IF(B24="","",VLOOKUP(S24,$AC$3:$AD$14,2,FALSE))
V25: =IF(E25="","",E25) | W25: =IF(B25="","",B25) | X25: =IF(B25="","",C25) | Y25: =IF(B25="","",D25) | Z25: =IF(B25="","",IF(G25=$C$2,I25,L25)) | AA25: =IF(B25="","",VLOOKUP(S25,$AC$3:$AD$14,2,FALSE))
V26: =IF(E26="","",E26) | W26: =IF(B26="","",B26) | X26: =IF(B26="","",C26) | Y26: =IF(B26="","",D26) | Z26: =IF(B26="","",IF(G26=$C$2,I26,L26)) | AA26: =IF(B26="","",VLOOKUP(S26,$AC$3:$AD$14,2,FALSE))
V27: =IF(E27="","",E27) | W27: =IF(B27="","",B27) | X27: =IF(B27="","",C27) | Y27: =IF(B27="","",D27) | Z27: =IF(B27="","",IF(G27=$C$2,I27,L27)) | AA27: =IF(B27="","",VLOOKUP(S27,$AC$3:$AD$14,2,FALSE))
V28: =IF(E28="","",E28) | W28: =IF(B28="","",B28) | X28: =IF(B28="","",C28) | Y28: =IF(B28="","",D28) | Z28: =IF(B28="","",IF(G28=$C$2,I28,L28)) | AA28: =IF(B28="","",VLOOKUP(S28,$AC$3:$AD$14,2,FALSE))
V29: =IF(E29="","",E29) | W29: =IF(B29="","",B29) | X29: =IF(B29="","",C29) | Y29: =IF(B29="","",D29) | Z29: =IF(B29="","",IF(G29=$C$2,I29,L29)) | AA29: =IF(B29="","",VLOOKUP(S29,$AC$3:$AD$14,2,FALSE))
V30: =IF(E30="","",E30) | W30: =IF(B30="","",B30) | X30: =IF(B30="","",C30) | Y30: =IF(B30="","",D30) | Z30: =IF(B30="","",IF(G30=$C$2,I30,L30)) | AA30: =IF(B30="","",VLOOKUP(S30,$AC$3:$AD$14,2,FALSE)) | AF30: Totaal | AI30: =SUM(AI19:AI29) -> 0
V31: =IF(E31="","",E31) | W31: =IF(B31="","",B31) | X31: =IF(B31="","",C31) | Y31: =IF(B31="","",D31) | Z31: =IF(B31="","",IF(G31=$C$2,I31,L31)) | AA31: =IF(B31="","",VLOOKUP(S31,$AC$3:$AD$14,2,FALSE))
V32: =IF(E32="","",E32) | W32: =IF(B32="","",B32) | X32: =IF(B32="","",C32) | Y32: =IF(B32="","",D32) | Z32: =IF(B32="","",IF(G32=$C$2,I32,L32)) | AA32: =IF(B32="","",VLOOKUP(S32,$AC$3:$AD$14,2,FALSE)) | AF32: Week: | AG32: =Dashboard!AN32 -> 11
V33: =IF(E33="","",E33) | W33: =IF(B33="","",B33) | X33: =IF(B33="","",C33) | Y33: =IF(B33="","",D33) | Z33: =IF(B33="","",IF(G33=$C$2,I33,L33)) | AA33: =IF(B33="","",VLOOKUP(S33,$AC$3:$AD$14,2,FALSE)) | AF33: Order: | AG33: Omschrijving | AH33: Klant: | AI33: Uren: | AJ33: Status:
V34: =IF(E34="","",E34) | W34: =IF(B34="","",B34) | X34: =IF(B34="","",C34) | Y34: =IF(B34="","",D34) | Z34: =IF(B34="","",IF(G34=$C$2,I34,L34)) | AA34: =IF(B34="","",VLOOKUP(S34,$AC$3:$AD$14,2,FALSE)) | AF34: {=_xlfn._xlws.FILTER($W$4:$AA$100,$V$4:$V$100=AG32,"")}
V35: =IF(E35="","",E35) | W35: =IF(B35="","",B35) | X35: =IF(B35="","",C35) | Y35: =IF(B35="","",D35) | Z35: =IF(B35="","",IF(G35=$C$2,I35,L35)) | AA35: =IF(B35="","",VLOOKUP(S35,$AC$3:$AD$14,2,FALSE))
V36: =IF(E36="","",E36) | W36: =IF(B36="","",B36) | X36: =IF(B36="","",C36) | Y36: =IF(B36="","",D36) | Z36: =IF(B36="","",IF(G36=$C$2,I36,L36)) | AA36: =IF(B36="","",VLOOKUP(S36,$AC$3:$AD$14,2,FALSE))
V37: =IF(E37="","",E37) | W37: =IF(B37="","",B37) | X37: =IF(B37="","",C37) | Y37: =IF(B37="","",D37) | Z37: =IF(B37="","",IF(G37=$C$2,I37,L37)) | AA37: =IF(B37="","",VLOOKUP(S37,$AC$3:$AD$14,2,FALSE))
V38: =IF(E38="","",E38) | W38: =IF(B38="","",B38) | X38: =IF(B38="","",C38) | Y38: =IF(B38="","",D38) | Z38: =IF(B38="","",IF(G38=$C$2,I38,L38)) | AA38: =IF(B38="","",VLOOKUP(S38,$AC$3:$AD$14,2,FALSE))
V39: =IF(E39="","",E39) | W39: =IF(B39="","",B39) | X39: =IF(B39="","",C39) | Y39: =IF(B39="","",D39) | Z39: =IF(B39="","",IF(G39=$C$2,I39,L39)) | AA39: =IF(B39="","",VLOOKUP(S39,$AC$3:$AD$14,2,FALSE))
V40: =IF(E40="","",E40) | W40: =IF(B40="","",B40) | X40: =IF(B40="","",C40) | Y40: =IF(B40="","",D40) | Z40: =IF(B40="","",IF(G40=$C$2,I40,L40)) | AA40: =IF(B40="","",VLOOKUP(S40,$AC$3:$AD$14,2,FALSE))
V41: =IF(E41="","",E41) | W41: =IF(B41="","",B41) | X41: =IF(B41="","",C41) | Y41: =IF(B41="","",D41) | Z41: =IF(B41="","",IF(G41=$C$2,I41,L41)) | AA41: =IF(B41="","",VLOOKUP(S41,$AC$3:$AD$14,2,FALSE))
...

Sheet Ber. Planning Ed
B2: Medewerker: | C2: Ed | AC2: Omrekening status: | AF2: Week: | AG2: =Dashboard!E32 -> 9
B3: Ordernummer: | C3: Omschrijving: | D3: Klant: | E3: Week: | F3: Totale uren: | G3: Medewerker 1: | H3: % uren 1: | I3: Uren 1: | J3: Medewerker 2: | K3: % uren 2: | L3: Uren 2: | M3: Medewerker 3: | N3: % uren 3: | O3: Uren 3: | P3: Controle % | Q3: Datum coater/verzinkerij: | R3: Datum gereed: | S3: Status: | T3: Hulpmaterialen: | V3: Week: | W3: Order: | X3: Omschrijving | Y3: Klant: | Z3: Uren: | AA3: Status: | AC3: Status: | AD3: Nummer: | AF3: Order: | AG3: Omschrijving | AH3: Klant: | AI3: Uren: | AJ3: Status:
B4: {=_xlfn._xlws.FILTER('Ber. Planning Totaal'!B4:T1000,('Ber. Planning Totaal'!G4:G1000=C2)+('Ber. Planning Totaal'!J4:J1000=C2)+('Ber. Planning Totaal'!M4:M1000=C2))} -> #VALUE! | V4: =IF(E4="","",E4) | W4: =IF(B4="","",B4) -> #VALUE! | X4: =IF(B4="","",C4) -> #VALUE! | Y4: =IF(B4="","",D4) -> #VALUE! | Z4: =IF(B4="","",IF(G4=$C$2,I4,L4)) -> #VALUE! | AA4: =IF(B4="","",VLOOKUP(S4,$AC$3:$AD$14,2,FALSE)) -> #VALUE! | AC4: 1 - Werkvoorbereiding | AD4: 1 | AF4: {=_xlfn._xlws.FILTER($W$4:$AA$100,$V$4:$V$100=AG2,"")}
V5: =IF(E5="","",E5) | W5: =IF(B5="","",B5) | X5: =IF(B5="","",C5) | Y5: =IF(B5="","",D5) | Z5: =IF(B5="","",IF(G5=$C$2,I5,L5)) | AA5: =IF(B5="","",VLOOKUP(S5,$AC$3:$AD$14,2,FALSE)) | AC5: 2 - Materiaal deels besteld | AD5: 2
V6: =IF(E6="","",E6) | W6: =IF(B6="","",B6) | X6: =IF(B6="","",C6) | Y6: =IF(B6="","",D6) | Z6: =IF(B6="","",IF(G6=$C$2,I6,L6)) | AA6: =IF(B6="","",VLOOKUP(S6,$AC$3:$AD$14,2,FALSE)) | AC6: 3 - Materiaal besteld | AD6: 3
V7: =IF(E7="","",E7) | W7: =IF(B7="","",B7) | X7: =IF(B7="","",C7) | Y7: =IF(B7="","",D7) | Z7: =IF(B7="","",IF(G7=$C$2,I7,L7)) | AA7: =IF(B7="","",VLOOKUP(S7,$AC$3:$AD$14,2,FALSE)) | AC7: 4 - Materiaal binnen | AD7: 4
V8: =IF(E8="","",E8) | W8: =IF(B8="","",B8) | X8: =IF(B8="","",C8) | Y8: =IF(B8="","",D8) | Z8: =IF(B8="","",IF(G8=$C$2,I8,L8)) | AA8: =IF(B8="","",VLOOKUP(S8,$AC$3:$AD$14,2,FALSE)) | AC8: 5 - Voorbereiden (Nobelweg 2B) | AD8: 5
V9: =IF(E9="","",E9) | W9: =IF(B9="","",B9) | X9: =IF(B9="","",C9) | Y9: =IF(B9="","",D9) | Z9: =IF(B9="","",IF(G9=$C$2,I9,L9)) | AA9: =IF(B9="","",VLOOKUP(S9,$AC$3:$AD$14,2,FALSE)) | AC9: 6 - In productie (Nobelweg 3) | AD9: 6
V10: =IF(E10="","",E10) | W10: =IF(B10="","",B10) | X10: =IF(B10="","",C10) | Y10: =IF(B10="","",D10) | Z10: =IF(B10="","",IF(G10=$C$2,I10,L10)) | AA10: =IF(B10="","",VLOOKUP(S10,$AC$3:$AD$14,2,FALSE)) | AC10: 7 - Klaar voor coater/verzinkerij | AD10: 7
V11: =IF(E11="","",E11) | W11: =IF(B11="","",B11) | X11: =IF(B11="","",C11) | Y11: =IF(B11="","",D11) | Z11: =IF(B11="","",IF(G11=$C$2,I11,L11)) | AA11: =IF(B11="","",VLOOKUP(S11,$AC$3:$AD$14,2,FALSE)) | AC11: 8 - Bij coater/verzinkerij | AD11: 8
V12: =IF(E12="","",E12) | W12: =IF(B12="","",B12) | X12: =IF(B12="","",C12) | Y12: =IF(B12="","",D12) | Z12: =IF(B12="","",IF(G12=$C$2,I12,L12)) | AA12: =IF(B12="","",VLOOKUP(S12,$AC$3:$AD$14,2,FALSE)) | AC12: 9 - Gereed, kan worden opgehaald | AD12: 9
V13: =IF(E13="","",E13) | W13: =IF(B13="","",B13) | X13: =IF(B13="","",C13) | Y13: =IF(B13="","",D13) | Z13: =IF(B13="","",IF(G13=$C$2,I13,L13)) | AA13: =IF(B13="","",VLOOKUP(S13,$AC$3:$AD$14,2,FALSE)) | AC13: 10 - Afgeleverd | AD13: 10
V14: =IF(E14="","",E14) | W14: =IF(B14="","",B14) | X14: =IF(B14="","",C14) | Y14: =IF(B14="","",D14) | Z14: =IF(B14="","",IF(G14=$C$2,I14,L14)) | AA14: =IF(B14="","",VLOOKUP(S14,$AC$3:$AD$14,2,FALSE)) | AC14: UITBESTEED | AD14: U
V15: =IF(E15="","",E15) | W15: =IF(B15="","",B15) | X15: =IF(B15="","",C15) | Y15: =IF(B15="","",D15) | Z15: =IF(B15="","",IF(G15=$C$2,I15,L15)) | AA15: =IF(B15="","",VLOOKUP(S15,$AC$3:$AD$14,2,FALSE)) | AF15: Totaal | AI15: =SUM(AI4:AI14) -> 0
V16: =IF(E16="","",E16) | W16: =IF(B16="","",B16) | X16: =IF(B16="","",C16) | Y16: =IF(B16="","",D16) | Z16: =IF(B16="","",IF(G16=$C$2,I16,L16)) | AA16: =IF(B16="","",VLOOKUP(S16,$AC$3:$AD$14,2,FALSE))
